[2025-04-03T09:43:44.666+0000] {taskinstance.py:1956} INFO - Dependencies all met for dep_context=non-requeueable deps ti=<TaskInstance: Web_Log_Processing.process_log_files scheduled__2025-04-02T00:00:00+00:00 [queued]>
[2025-04-03T09:43:44.676+0000] {taskinstance.py:1956} INFO - Dependencies all met for dep_context=requeueable deps ti=<TaskInstance: Web_Log_Processing.process_log_files scheduled__2025-04-02T00:00:00+00:00 [queued]>
[2025-04-03T09:43:44.677+0000] {taskinstance.py:2170} INFO - Starting attempt 2 of 4
[2025-04-03T09:43:44.691+0000] {taskinstance.py:2191} INFO - Executing <Task(PythonOperator): process_log_files> on 2025-04-02 00:00:00+00:00
[2025-04-03T09:43:44.696+0000] {standard_task_runner.py:60} INFO - Started process 316 to run task
[2025-04-03T09:43:44.700+0000] {standard_task_runner.py:87} INFO - Running: ['***', 'tasks', 'run', 'Web_Log_Processing', 'process_log_files', 'scheduled__2025-04-02T00:00:00+00:00', '--job-id', '3', '--raw', '--subdir', 'DAGS_FOLDER/w3c.py', '--cfg-path', '/tmp/tmpj0rab4ko']
[2025-04-03T09:43:44.704+0000] {standard_task_runner.py:88} INFO - Job 3: Subtask process_log_files
[2025-04-03T09:43:44.766+0000] {task_command.py:423} INFO - Running <TaskInstance: Web_Log_Processing.process_log_files scheduled__2025-04-02T00:00:00+00:00 [running]> on host 72a8ea729061
[2025-04-03T09:43:45.002+0000] {taskinstance.py:2480} INFO - Exporting env vars: AIRFLOW_CTX_DAG_OWNER='***' AIRFLOW_CTX_DAG_ID='Web_Log_Processing' AIRFLOW_CTX_TASK_ID='process_log_files' AIRFLOW_CTX_EXECUTION_DATE='2025-04-02T00:00:00+00:00' AIRFLOW_CTX_TRY_NUMBER='2' AIRFLOW_CTX_DAG_RUN_ID='scheduled__2025-04-02T00:00:00+00:00'
[2025-04-03T09:43:45.013+0000] {taskinstance.py:2698} ERROR - Task failed with exception
Traceback (most recent call last):
  File "/opt/airflow/dags/w3c.py", line 111, in process_logs
    raise AirflowException("No valid log entries found in the log files.")
airflow.exceptions.AirflowException: No valid log entries found in the log files.

During handling of the above exception, another exception occurred:

Traceback (most recent call last):
  File "/home/airflow/.local/lib/python3.8/site-packages/airflow/models/taskinstance.py", line 433, in _execute_task
    result = execute_callable(context=context, **execute_callable_kwargs)
  File "/home/airflow/.local/lib/python3.8/site-packages/airflow/operators/python.py", line 199, in execute
    return_value = self.execute_callable()
  File "/home/airflow/.local/lib/python3.8/site-packages/airflow/operators/python.py", line 216, in execute_callable
    return self.python_callable(*self.op_args, **self.op_kwargs)
  File "/opt/airflow/dags/w3c.py", line 151, in process_logs
    raise AirflowException(f"Log processing failed: {str(e)}")
airflow.exceptions.AirflowException: Log processing failed: No valid log entries found in the log files.
[2025-04-03T09:43:45.025+0000] {taskinstance.py:1138} INFO - Marking task as UP_FOR_RETRY. dag_id=Web_Log_Processing, task_id=process_log_files, execution_date=20250402T000000, start_date=20250403T094344, end_date=20250403T094345
[2025-04-03T09:43:45.038+0000] {standard_task_runner.py:107} ERROR - Failed to execute job 3 for task process_log_files (Log processing failed: No valid log entries found in the log files.; 316)
[2025-04-03T09:43:45.076+0000] {local_task_job_runner.py:234} INFO - Task exited with return code 1
[2025-04-03T09:43:45.099+0000] {taskinstance.py:3280} INFO - 0 downstream tasks scheduled from follow-on schedule check
[2025-04-03T10:12:48.934+0000] {taskinstance.py:1956} INFO - Dependencies all met for dep_context=non-requeueable deps ti=<TaskInstance: Web_Log_Processing.process_log_files scheduled__2025-04-02T00:00:00+00:00 [queued]>
[2025-04-03T10:12:48.946+0000] {taskinstance.py:1956} INFO - Dependencies all met for dep_context=requeueable deps ti=<TaskInstance: Web_Log_Processing.process_log_files scheduled__2025-04-02T00:00:00+00:00 [queued]>
[2025-04-03T10:12:48.947+0000] {taskinstance.py:2170} INFO - Starting attempt 2 of 4
[2025-04-03T10:12:48.968+0000] {taskinstance.py:2191} INFO - Executing <Task(PythonOperator): process_log_files> on 2025-04-02 00:00:00+00:00
[2025-04-03T10:12:48.975+0000] {standard_task_runner.py:60} INFO - Started process 316 to run task
[2025-04-03T10:12:48.980+0000] {standard_task_runner.py:87} INFO - Running: ['***', 'tasks', 'run', 'Web_Log_Processing', 'process_log_files', 'scheduled__2025-04-02T00:00:00+00:00', '--job-id', '3', '--raw', '--subdir', 'DAGS_FOLDER/w3c.py', '--cfg-path', '/tmp/tmp8oq9ql92']
[2025-04-03T10:12:48.983+0000] {standard_task_runner.py:88} INFO - Job 3: Subtask process_log_files
[2025-04-03T10:12:49.048+0000] {task_command.py:423} INFO - Running <TaskInstance: Web_Log_Processing.process_log_files scheduled__2025-04-02T00:00:00+00:00 [running]> on host bf44a9d0d837
[2025-04-03T10:12:49.326+0000] {taskinstance.py:2480} INFO - Exporting env vars: AIRFLOW_CTX_DAG_OWNER='***' AIRFLOW_CTX_DAG_ID='Web_Log_Processing' AIRFLOW_CTX_TASK_ID='process_log_files' AIRFLOW_CTX_EXECUTION_DATE='2025-04-02T00:00:00+00:00' AIRFLOW_CTX_TRY_NUMBER='2' AIRFLOW_CTX_DAG_RUN_ID='scheduled__2025-04-02T00:00:00+00:00'
[2025-04-03T10:12:49.329+0000] {logging_mixin.py:188} INFO - Looking for log files in: d:/Documents/UK/University/BI/Repo/***-etl/data
[2025-04-03T10:12:49.330+0000] {logging_mixin.py:188} INFO - Files found: []
[2025-04-03T10:12:49.342+0000] {taskinstance.py:2698} ERROR - Task failed with exception
Traceback (most recent call last):
  File "/opt/airflow/dags/w3c.py", line 117, in process_logs
    raise AirflowException("No valid log entries found in the log files.")
airflow.exceptions.AirflowException: No valid log entries found in the log files.

During handling of the above exception, another exception occurred:

Traceback (most recent call last):
  File "/home/airflow/.local/lib/python3.8/site-packages/airflow/models/taskinstance.py", line 433, in _execute_task
    result = execute_callable(context=context, **execute_callable_kwargs)
  File "/home/airflow/.local/lib/python3.8/site-packages/airflow/operators/python.py", line 199, in execute
    return_value = self.execute_callable()
  File "/home/airflow/.local/lib/python3.8/site-packages/airflow/operators/python.py", line 216, in execute_callable
    return self.python_callable(*self.op_args, **self.op_kwargs)
  File "/opt/airflow/dags/w3c.py", line 157, in process_logs
    raise AirflowException(f"Log processing failed: {str(e)}")
airflow.exceptions.AirflowException: Log processing failed: No valid log entries found in the log files.
[2025-04-03T10:12:49.355+0000] {taskinstance.py:1138} INFO - Marking task as UP_FOR_RETRY. dag_id=Web_Log_Processing, task_id=process_log_files, execution_date=20250402T000000, start_date=20250403T101248, end_date=20250403T101249
[2025-04-03T10:12:49.370+0000] {standard_task_runner.py:107} ERROR - Failed to execute job 3 for task process_log_files (Log processing failed: No valid log entries found in the log files.; 316)
[2025-04-03T10:12:49.434+0000] {local_task_job_runner.py:234} INFO - Task exited with return code 1
[2025-04-03T10:12:49.462+0000] {taskinstance.py:3280} INFO - 0 downstream tasks scheduled from follow-on schedule check
[2025-04-03T10:29:35.551+0000] {taskinstance.py:1956} INFO - Dependencies all met for dep_context=non-requeueable deps ti=<TaskInstance: Web_Log_Processing.process_log_files scheduled__2025-04-02T00:00:00+00:00 [queued]>
[2025-04-03T10:29:35.564+0000] {taskinstance.py:1956} INFO - Dependencies all met for dep_context=requeueable deps ti=<TaskInstance: Web_Log_Processing.process_log_files scheduled__2025-04-02T00:00:00+00:00 [queued]>
[2025-04-03T10:29:35.565+0000] {taskinstance.py:2170} INFO - Starting attempt 2 of 4
[2025-04-03T10:29:35.582+0000] {taskinstance.py:2191} INFO - Executing <Task(PythonOperator): process_log_files> on 2025-04-02 00:00:00+00:00
[2025-04-03T10:29:35.587+0000] {standard_task_runner.py:60} INFO - Started process 382 to run task
[2025-04-03T10:29:35.592+0000] {standard_task_runner.py:87} INFO - Running: ['***', 'tasks', 'run', 'Web_Log_Processing', 'process_log_files', 'scheduled__2025-04-02T00:00:00+00:00', '--job-id', '3', '--raw', '--subdir', 'DAGS_FOLDER/w3c.py', '--cfg-path', '/tmp/tmpbudu3l22']
[2025-04-03T10:29:35.595+0000] {standard_task_runner.py:88} INFO - Job 3: Subtask process_log_files
[2025-04-03T10:29:35.660+0000] {task_command.py:423} INFO - Running <TaskInstance: Web_Log_Processing.process_log_files scheduled__2025-04-02T00:00:00+00:00 [running]> on host a086d075ccfe
[2025-04-03T10:29:35.939+0000] {taskinstance.py:2480} INFO - Exporting env vars: AIRFLOW_CTX_DAG_OWNER='***' AIRFLOW_CTX_DAG_ID='Web_Log_Processing' AIRFLOW_CTX_TASK_ID='process_log_files' AIRFLOW_CTX_EXECUTION_DATE='2025-04-02T00:00:00+00:00' AIRFLOW_CTX_TRY_NUMBER='2' AIRFLOW_CTX_DAG_RUN_ID='scheduled__2025-04-02T00:00:00+00:00'
[2025-04-03T10:29:35.943+0000] {logging_mixin.py:188} INFO - Looking for log files in: d:/Documents/UK/University/BI/Repo/***-etl/data
[2025-04-03T10:29:35.945+0000] {logging_mixin.py:188} INFO - Files found: []
[2025-04-03T10:29:35.958+0000] {taskinstance.py:2698} ERROR - Task failed with exception
Traceback (most recent call last):
  File "/opt/airflow/dags/w3c.py", line 117, in process_logs
    raise AirflowException("No valid log entries found in the log files.")
airflow.exceptions.AirflowException: No valid log entries found in the log files.

During handling of the above exception, another exception occurred:

Traceback (most recent call last):
  File "/home/airflow/.local/lib/python3.8/site-packages/airflow/models/taskinstance.py", line 433, in _execute_task
    result = execute_callable(context=context, **execute_callable_kwargs)
  File "/home/airflow/.local/lib/python3.8/site-packages/airflow/operators/python.py", line 199, in execute
    return_value = self.execute_callable()
  File "/home/airflow/.local/lib/python3.8/site-packages/airflow/operators/python.py", line 216, in execute_callable
    return self.python_callable(*self.op_args, **self.op_kwargs)
  File "/opt/airflow/dags/w3c.py", line 157, in process_logs
    raise AirflowException(f"Log processing failed: {str(e)}")
airflow.exceptions.AirflowException: Log processing failed: No valid log entries found in the log files.
[2025-04-03T10:29:35.970+0000] {taskinstance.py:1138} INFO - Marking task as UP_FOR_RETRY. dag_id=Web_Log_Processing, task_id=process_log_files, execution_date=20250402T000000, start_date=20250403T102935, end_date=20250403T102935
[2025-04-03T10:29:35.984+0000] {standard_task_runner.py:107} ERROR - Failed to execute job 3 for task process_log_files (Log processing failed: No valid log entries found in the log files.; 382)
[2025-04-03T10:29:36.007+0000] {local_task_job_runner.py:234} INFO - Task exited with return code 1
[2025-04-03T10:29:36.031+0000] {taskinstance.py:3280} INFO - 0 downstream tasks scheduled from follow-on schedule check
