[2025-04-03T09:47:59.474+0000] {taskinstance.py:1956} INFO - Dependencies all met for dep_context=non-requeueable deps ti=<TaskInstance: Web_Log_Processing.process_log_files scheduled__2025-04-02T00:00:00+00:00 [queued]>
[2025-04-03T09:47:59.482+0000] {taskinstance.py:1956} INFO - Dependencies all met for dep_context=requeueable deps ti=<TaskInstance: Web_Log_Processing.process_log_files scheduled__2025-04-02T00:00:00+00:00 [queued]>
[2025-04-03T09:47:59.482+0000] {taskinstance.py:2170} INFO - Starting attempt 3 of 6
[2025-04-03T09:47:59.547+0000] {taskinstance.py:2191} INFO - Executing <Task(PythonOperator): process_log_files> on 2025-04-02 00:00:00+00:00
[2025-04-03T09:47:59.560+0000] {standard_task_runner.py:60} INFO - Started process 407 to run task
[2025-04-03T09:47:59.564+0000] {standard_task_runner.py:87} INFO - Running: ['***', 'tasks', 'run', 'Web_Log_Processing', 'process_log_files', 'scheduled__2025-04-02T00:00:00+00:00', '--job-id', '4', '--raw', '--subdir', 'DAGS_FOLDER/w3c.py', '--cfg-path', '/tmp/tmp_t9dvbqe']
[2025-04-03T09:47:59.567+0000] {standard_task_runner.py:88} INFO - Job 4: Subtask process_log_files
[2025-04-03T09:47:59.626+0000] {task_command.py:423} INFO - Running <TaskInstance: Web_Log_Processing.process_log_files scheduled__2025-04-02T00:00:00+00:00 [running]> on host 72a8ea729061
[2025-04-03T09:47:59.987+0000] {taskinstance.py:2480} INFO - Exporting env vars: AIRFLOW_CTX_DAG_OWNER='***' AIRFLOW_CTX_DAG_ID='Web_Log_Processing' AIRFLOW_CTX_TASK_ID='process_log_files' AIRFLOW_CTX_EXECUTION_DATE='2025-04-02T00:00:00+00:00' AIRFLOW_CTX_TRY_NUMBER='3' AIRFLOW_CTX_DAG_RUN_ID='scheduled__2025-04-02T00:00:00+00:00'
[2025-04-03T09:48:00.001+0000] {taskinstance.py:2698} ERROR - Task failed with exception
Traceback (most recent call last):
  File "/opt/airflow/dags/w3c.py", line 111, in process_logs
    raise AirflowException("No valid log entries found in the log files.")
airflow.exceptions.AirflowException: No valid log entries found in the log files.

During handling of the above exception, another exception occurred:

Traceback (most recent call last):
  File "/home/airflow/.local/lib/python3.8/site-packages/airflow/models/taskinstance.py", line 433, in _execute_task
    result = execute_callable(context=context, **execute_callable_kwargs)
  File "/home/airflow/.local/lib/python3.8/site-packages/airflow/operators/python.py", line 199, in execute
    return_value = self.execute_callable()
  File "/home/airflow/.local/lib/python3.8/site-packages/airflow/operators/python.py", line 216, in execute_callable
    return self.python_callable(*self.op_args, **self.op_kwargs)
  File "/opt/airflow/dags/w3c.py", line 151, in process_logs
    raise AirflowException(f"Log processing failed: {str(e)}")
airflow.exceptions.AirflowException: Log processing failed: No valid log entries found in the log files.
[2025-04-03T09:48:00.019+0000] {taskinstance.py:1138} INFO - Marking task as UP_FOR_RETRY. dag_id=Web_Log_Processing, task_id=process_log_files, execution_date=20250402T000000, start_date=20250403T094759, end_date=20250403T094800
[2025-04-03T09:48:00.035+0000] {standard_task_runner.py:107} ERROR - Failed to execute job 4 for task process_log_files (Log processing failed: No valid log entries found in the log files.; 407)
[2025-04-03T09:48:00.059+0000] {local_task_job_runner.py:234} INFO - Task exited with return code 1
[2025-04-03T09:48:00.094+0000] {taskinstance.py:3280} INFO - 0 downstream tasks scheduled from follow-on schedule check
[2025-04-03T10:17:50.972+0000] {taskinstance.py:1956} INFO - Dependencies all met for dep_context=non-requeueable deps ti=<TaskInstance: Web_Log_Processing.process_log_files scheduled__2025-04-02T00:00:00+00:00 [queued]>
[2025-04-03T10:17:50.982+0000] {taskinstance.py:1956} INFO - Dependencies all met for dep_context=requeueable deps ti=<TaskInstance: Web_Log_Processing.process_log_files scheduled__2025-04-02T00:00:00+00:00 [queued]>
[2025-04-03T10:17:50.983+0000] {taskinstance.py:2170} INFO - Starting attempt 3 of 4
[2025-04-03T10:17:50.999+0000] {taskinstance.py:2191} INFO - Executing <Task(PythonOperator): process_log_files> on 2025-04-02 00:00:00+00:00
[2025-04-03T10:17:51.005+0000] {standard_task_runner.py:60} INFO - Started process 423 to run task
[2025-04-03T10:17:51.009+0000] {standard_task_runner.py:87} INFO - Running: ['***', 'tasks', 'run', 'Web_Log_Processing', 'process_log_files', 'scheduled__2025-04-02T00:00:00+00:00', '--job-id', '4', '--raw', '--subdir', 'DAGS_FOLDER/w3c.py', '--cfg-path', '/tmp/tmp0gatnobv']
[2025-04-03T10:17:51.012+0000] {standard_task_runner.py:88} INFO - Job 4: Subtask process_log_files
[2025-04-03T10:17:51.081+0000] {task_command.py:423} INFO - Running <TaskInstance: Web_Log_Processing.process_log_files scheduled__2025-04-02T00:00:00+00:00 [running]> on host bf44a9d0d837
[2025-04-03T10:17:51.370+0000] {taskinstance.py:2480} INFO - Exporting env vars: AIRFLOW_CTX_DAG_OWNER='***' AIRFLOW_CTX_DAG_ID='Web_Log_Processing' AIRFLOW_CTX_TASK_ID='process_log_files' AIRFLOW_CTX_EXECUTION_DATE='2025-04-02T00:00:00+00:00' AIRFLOW_CTX_TRY_NUMBER='3' AIRFLOW_CTX_DAG_RUN_ID='scheduled__2025-04-02T00:00:00+00:00'
[2025-04-03T10:17:51.372+0000] {logging_mixin.py:188} INFO - Looking for log files in: d:/Documents/UK/University/BI/Repo/***-etl/data
[2025-04-03T10:17:51.373+0000] {logging_mixin.py:188} INFO - Files found: []
[2025-04-03T10:17:51.383+0000] {taskinstance.py:2698} ERROR - Task failed with exception
Traceback (most recent call last):
  File "/opt/airflow/dags/w3c.py", line 117, in process_logs
    raise AirflowException("No valid log entries found in the log files.")
airflow.exceptions.AirflowException: No valid log entries found in the log files.

During handling of the above exception, another exception occurred:

Traceback (most recent call last):
  File "/home/airflow/.local/lib/python3.8/site-packages/airflow/models/taskinstance.py", line 433, in _execute_task
    result = execute_callable(context=context, **execute_callable_kwargs)
  File "/home/airflow/.local/lib/python3.8/site-packages/airflow/operators/python.py", line 199, in execute
    return_value = self.execute_callable()
  File "/home/airflow/.local/lib/python3.8/site-packages/airflow/operators/python.py", line 216, in execute_callable
    return self.python_callable(*self.op_args, **self.op_kwargs)
  File "/opt/airflow/dags/w3c.py", line 157, in process_logs
    raise AirflowException(f"Log processing failed: {str(e)}")
airflow.exceptions.AirflowException: Log processing failed: No valid log entries found in the log files.
[2025-04-03T10:17:51.398+0000] {taskinstance.py:1138} INFO - Marking task as UP_FOR_RETRY. dag_id=Web_Log_Processing, task_id=process_log_files, execution_date=20250402T000000, start_date=20250403T101750, end_date=20250403T101751
[2025-04-03T10:17:51.417+0000] {standard_task_runner.py:107} ERROR - Failed to execute job 4 for task process_log_files (Log processing failed: No valid log entries found in the log files.; 423)
[2025-04-03T10:17:51.463+0000] {local_task_job_runner.py:234} INFO - Task exited with return code 1
[2025-04-03T10:17:51.489+0000] {taskinstance.py:3280} INFO - 0 downstream tasks scheduled from follow-on schedule check
