[2025-04-02T18:10:40.740+0000] {taskinstance.py:1956} INFO - Dependencies all met for dep_context=non-requeueable deps ti=<TaskInstance: Web_Log_Processing.process_log_files manual__2025-04-02T16:44:23.450643+00:00 [queued]>
[2025-04-02T18:10:40.754+0000] {taskinstance.py:1956} INFO - Dependencies all met for dep_context=requeueable deps ti=<TaskInstance: Web_Log_Processing.process_log_files manual__2025-04-02T16:44:23.450643+00:00 [queued]>
[2025-04-02T18:10:40.756+0000] {taskinstance.py:2170} INFO - Starting attempt 3 of 4
[2025-04-02T18:10:40.774+0000] {taskinstance.py:2191} INFO - Executing <Task(PythonOperator): process_log_files> on 2025-04-02 16:44:23.450643+00:00
[2025-04-02T18:10:40.782+0000] {standard_task_runner.py:60} INFO - Started process 1027 to run task
[2025-04-02T18:10:40.786+0000] {standard_task_runner.py:87} INFO - Running: ['***', 'tasks', 'run', 'Web_Log_Processing', 'process_log_files', 'manual__2025-04-02T16:44:23.450643+00:00', '--job-id', '21', '--raw', '--subdir', 'DAGS_FOLDER/w3c.py', '--cfg-path', '/tmp/tmpm5xnq36j']
[2025-04-02T18:10:40.790+0000] {standard_task_runner.py:88} INFO - Job 21: Subtask process_log_files
[2025-04-02T18:10:40.896+0000] {task_command.py:423} INFO - Running <TaskInstance: Web_Log_Processing.process_log_files manual__2025-04-02T16:44:23.450643+00:00 [running]> on host e3653afa66c4
[2025-04-02T18:10:41.280+0000] {taskinstance.py:2480} INFO - Exporting env vars: AIRFLOW_CTX_DAG_OWNER='***' AIRFLOW_CTX_DAG_ID='Web_Log_Processing' AIRFLOW_CTX_TASK_ID='process_log_files' AIRFLOW_CTX_EXECUTION_DATE='2025-04-02T16:44:23.450643+00:00' AIRFLOW_CTX_TRY_NUMBER='3' AIRFLOW_CTX_DAG_RUN_ID='manual__2025-04-02T16:44:23.450643+00:00'
[2025-04-02T18:10:41.316+0000] {taskinstance.py:2698} ERROR - Task failed with exception
Traceback (most recent call last):
  File "/opt/airflow/dags/w3c.py", line 62, in process_logs
    df = pd.DataFrame(combined_data, columns=columns[:len(combined_data[0])])
IndexError: list index out of range

During handling of the above exception, another exception occurred:

Traceback (most recent call last):
  File "/home/airflow/.local/lib/python3.8/site-packages/airflow/models/taskinstance.py", line 433, in _execute_task
    result = execute_callable(context=context, **execute_callable_kwargs)
  File "/home/airflow/.local/lib/python3.8/site-packages/airflow/operators/python.py", line 199, in execute
    return_value = self.execute_callable()
  File "/home/airflow/.local/lib/python3.8/site-packages/airflow/operators/python.py", line 216, in execute_callable
    return self.python_callable(*self.op_args, **self.op_kwargs)
  File "/opt/airflow/dags/w3c.py", line 85, in process_logs
    raise AirflowException(f"Log processing failed: {str(e)}")
airflow.exceptions.AirflowException: Log processing failed: list index out of range
[2025-04-02T18:10:41.330+0000] {taskinstance.py:1138} INFO - Marking task as UP_FOR_RETRY. dag_id=Web_Log_Processing, task_id=process_log_files, execution_date=20250402T164423, start_date=20250402T181040, end_date=20250402T181041
[2025-04-02T18:10:41.346+0000] {standard_task_runner.py:107} ERROR - Failed to execute job 21 for task process_log_files (Log processing failed: list index out of range; 1027)
[2025-04-02T18:10:41.363+0000] {local_task_job_runner.py:234} INFO - Task exited with return code 1
[2025-04-02T18:10:41.389+0000] {taskinstance.py:3280} INFO - 0 downstream tasks scheduled from follow-on schedule check
