[2025-04-02T15:30:01.593+0000] {taskinstance.py:1956} INFO - Dependencies all met for dep_context=non-requeueable deps ti=<TaskInstance: People_Data_Pipeline.ensure_people_table scheduled__2025-04-01T00:00:00+00:00 [queued]>
[2025-04-02T15:30:01.604+0000] {taskinstance.py:1956} INFO - Dependencies all met for dep_context=requeueable deps ti=<TaskInstance: People_Data_Pipeline.ensure_people_table scheduled__2025-04-01T00:00:00+00:00 [queued]>
[2025-04-02T15:30:01.605+0000] {taskinstance.py:2170} INFO - Starting attempt 1 of 3
[2025-04-02T15:30:01.622+0000] {taskinstance.py:2191} INFO - Executing <Task(PythonOperator): ensure_people_table> on 2025-04-01 00:00:00+00:00
[2025-04-02T15:30:01.627+0000] {standard_task_runner.py:60} INFO - Started process 570 to run task
[2025-04-02T15:30:01.631+0000] {standard_task_runner.py:87} INFO - Running: ['***', 'tasks', 'run', 'People_Data_Pipeline', 'ensure_people_table', 'scheduled__2025-04-01T00:00:00+00:00', '--job-id', '2', '--raw', '--subdir', 'DAGS_FOLDER/people_dag.py', '--cfg-path', '/tmp/tmp0vys1e8l']
[2025-04-02T15:30:01.634+0000] {standard_task_runner.py:88} INFO - Job 2: Subtask ensure_people_table
[2025-04-02T15:30:01.702+0000] {task_command.py:423} INFO - Running <TaskInstance: People_Data_Pipeline.ensure_people_table scheduled__2025-04-01T00:00:00+00:00 [running]> on host decb7b281929
[2025-04-02T15:30:01.797+0000] {taskinstance.py:2480} INFO - Exporting env vars: AIRFLOW_CTX_DAG_OWNER='***' AIRFLOW_CTX_DAG_ID='People_Data_Pipeline' AIRFLOW_CTX_TASK_ID='ensure_people_table' AIRFLOW_CTX_EXECUTION_DATE='2025-04-01T00:00:00+00:00' AIRFLOW_CTX_TRY_NUMBER='1' AIRFLOW_CTX_DAG_RUN_ID='scheduled__2025-04-01T00:00:00+00:00'
[2025-04-02T15:30:01.822+0000] {taskinstance.py:2698} ERROR - Task failed with exception
Traceback (most recent call last):
  File "/home/airflow/.local/lib/python3.8/site-packages/airflow/models/taskinstance.py", line 433, in _execute_task
    result = execute_callable(context=context, **execute_callable_kwargs)
  File "/home/airflow/.local/lib/python3.8/site-packages/airflow/operators/python.py", line 199, in execute
    return_value = self.execute_callable()
  File "/home/airflow/.local/lib/python3.8/site-packages/airflow/operators/python.py", line 216, in execute_callable
    return self.python_callable(*self.op_args, **self.op_kwargs)
  File "/opt/airflow/dags/people_dag.py", line 85, in ensure_people_table
    postgres_hook.run(CREATE_PEOPLE_TABLE_SQL)
  File "/home/airflow/.local/lib/python3.8/site-packages/airflow/providers/common/sql/hooks/sql.py", line 391, in run
    with closing(self.get_conn()) as conn:
  File "/home/airflow/.local/lib/python3.8/site-packages/airflow/providers/postgres/hooks/postgres.py", line 128, in get_conn
    conn = deepcopy(self.connection or self.get_connection(conn_id))
  File "/home/airflow/.local/lib/python3.8/site-packages/airflow/hooks/base.py", line 82, in get_connection
    conn = Connection.get_connection_from_secrets(conn_id)
  File "/home/airflow/.local/lib/python3.8/site-packages/airflow/models/connection.py", line 479, in get_connection_from_secrets
    raise AirflowNotFoundException(f"The conn_id `{conn_id}` isn't defined")
airflow.exceptions.AirflowNotFoundException: The conn_id `postgres_default` isn't defined
[2025-04-02T15:30:01.842+0000] {taskinstance.py:1138} INFO - Marking task as UP_FOR_RETRY. dag_id=People_Data_Pipeline, task_id=ensure_people_table, execution_date=20250401T000000, start_date=20250402T153001, end_date=20250402T153001
[2025-04-02T15:30:01.861+0000] {standard_task_runner.py:107} ERROR - Failed to execute job 2 for task ensure_people_table (The conn_id `postgres_default` isn't defined; 570)
[2025-04-02T15:30:01.886+0000] {local_task_job_runner.py:234} INFO - Task exited with return code 1
[2025-04-02T15:30:01.923+0000] {taskinstance.py:3280} INFO - 0 downstream tasks scheduled from follow-on schedule check
[2025-04-02T15:54:20.120+0000] {taskinstance.py:1956} INFO - Dependencies all met for dep_context=non-requeueable deps ti=<TaskInstance: People_Data_Pipeline.ensure_people_table scheduled__2025-04-01T00:00:00+00:00 [queued]>
[2025-04-02T15:54:20.132+0000] {taskinstance.py:1956} INFO - Dependencies all met for dep_context=requeueable deps ti=<TaskInstance: People_Data_Pipeline.ensure_people_table scheduled__2025-04-01T00:00:00+00:00 [queued]>
[2025-04-02T15:54:20.133+0000] {taskinstance.py:2170} INFO - Starting attempt 1 of 3
[2025-04-02T15:54:20.193+0000] {taskinstance.py:2191} INFO - Executing <Task(PythonOperator): ensure_people_table> on 2025-04-01 00:00:00+00:00
[2025-04-02T15:54:20.201+0000] {standard_task_runner.py:60} INFO - Started process 200 to run task
[2025-04-02T15:54:20.208+0000] {standard_task_runner.py:87} INFO - Running: ['***', 'tasks', 'run', 'People_Data_Pipeline', 'ensure_people_table', 'scheduled__2025-04-01T00:00:00+00:00', '--job-id', '2', '--raw', '--subdir', 'DAGS_FOLDER/people_dag.py', '--cfg-path', '/tmp/tmpplpdz6dq']
[2025-04-02T15:54:20.213+0000] {standard_task_runner.py:88} INFO - Job 2: Subtask ensure_people_table
[2025-04-02T15:54:20.303+0000] {task_command.py:423} INFO - Running <TaskInstance: People_Data_Pipeline.ensure_people_table scheduled__2025-04-01T00:00:00+00:00 [running]> on host e8d989b91ca4
[2025-04-02T15:54:20.536+0000] {taskinstance.py:2480} INFO - Exporting env vars: AIRFLOW_CTX_DAG_OWNER='***' AIRFLOW_CTX_DAG_ID='People_Data_Pipeline' AIRFLOW_CTX_TASK_ID='ensure_people_table' AIRFLOW_CTX_EXECUTION_DATE='2025-04-01T00:00:00+00:00' AIRFLOW_CTX_TRY_NUMBER='1' AIRFLOW_CTX_DAG_RUN_ID='scheduled__2025-04-01T00:00:00+00:00'
[2025-04-02T15:54:20.570+0000] {taskinstance.py:2698} ERROR - Task failed with exception
Traceback (most recent call last):
  File "/home/airflow/.local/lib/python3.8/site-packages/airflow/models/taskinstance.py", line 433, in _execute_task
    result = execute_callable(context=context, **execute_callable_kwargs)
  File "/home/airflow/.local/lib/python3.8/site-packages/airflow/operators/python.py", line 199, in execute
    return_value = self.execute_callable()
  File "/home/airflow/.local/lib/python3.8/site-packages/airflow/operators/python.py", line 216, in execute_callable
    return self.python_callable(*self.op_args, **self.op_kwargs)
  File "/opt/airflow/dags/people_dag.py", line 85, in ensure_people_table
    postgres_hook.run(CREATE_PEOPLE_TABLE_SQL)
  File "/home/airflow/.local/lib/python3.8/site-packages/airflow/providers/common/sql/hooks/sql.py", line 391, in run
    with closing(self.get_conn()) as conn:
  File "/home/airflow/.local/lib/python3.8/site-packages/airflow/providers/postgres/hooks/postgres.py", line 128, in get_conn
    conn = deepcopy(self.connection or self.get_connection(conn_id))
  File "/home/airflow/.local/lib/python3.8/site-packages/airflow/hooks/base.py", line 82, in get_connection
    conn = Connection.get_connection_from_secrets(conn_id)
  File "/home/airflow/.local/lib/python3.8/site-packages/airflow/models/connection.py", line 479, in get_connection_from_secrets
    raise AirflowNotFoundException(f"The conn_id `{conn_id}` isn't defined")
airflow.exceptions.AirflowNotFoundException: The conn_id `postgres_default` isn't defined
[2025-04-02T15:54:20.584+0000] {taskinstance.py:1138} INFO - Marking task as UP_FOR_RETRY. dag_id=People_Data_Pipeline, task_id=ensure_people_table, execution_date=20250401T000000, start_date=20250402T155420, end_date=20250402T155420
[2025-04-02T15:54:20.640+0000] {standard_task_runner.py:107} ERROR - Failed to execute job 2 for task ensure_people_table (The conn_id `postgres_default` isn't defined; 200)
[2025-04-02T15:54:20.664+0000] {local_task_job_runner.py:234} INFO - Task exited with return code 1
[2025-04-02T15:54:20.695+0000] {taskinstance.py:3280} INFO - 0 downstream tasks scheduled from follow-on schedule check
[2025-04-02T16:08:26.868+0000] {taskinstance.py:1956} INFO - Dependencies all met for dep_context=non-requeueable deps ti=<TaskInstance: People_Data_Pipeline.ensure_people_table scheduled__2025-04-01T00:00:00+00:00 [queued]>
[2025-04-02T16:08:26.880+0000] {taskinstance.py:1956} INFO - Dependencies all met for dep_context=requeueable deps ti=<TaskInstance: People_Data_Pipeline.ensure_people_table scheduled__2025-04-01T00:00:00+00:00 [queued]>
[2025-04-02T16:08:26.881+0000] {taskinstance.py:2170} INFO - Starting attempt 1 of 3
[2025-04-02T16:08:26.899+0000] {taskinstance.py:2191} INFO - Executing <Task(PythonOperator): ensure_people_table> on 2025-04-01 00:00:00+00:00
[2025-04-02T16:08:26.905+0000] {standard_task_runner.py:60} INFO - Started process 210 to run task
[2025-04-02T16:08:26.909+0000] {standard_task_runner.py:87} INFO - Running: ['***', 'tasks', 'run', 'People_Data_Pipeline', 'ensure_people_table', 'scheduled__2025-04-01T00:00:00+00:00', '--job-id', '2', '--raw', '--subdir', 'DAGS_FOLDER/people_dag.py', '--cfg-path', '/tmp/tmp8bxjufj4']
[2025-04-02T16:08:26.911+0000] {standard_task_runner.py:88} INFO - Job 2: Subtask ensure_people_table
[2025-04-02T16:08:26.974+0000] {task_command.py:423} INFO - Running <TaskInstance: People_Data_Pipeline.ensure_people_table scheduled__2025-04-01T00:00:00+00:00 [running]> on host 4c976e0a7b20
[2025-04-02T16:08:27.122+0000] {taskinstance.py:2480} INFO - Exporting env vars: AIRFLOW_CTX_DAG_OWNER='***' AIRFLOW_CTX_DAG_ID='People_Data_Pipeline' AIRFLOW_CTX_TASK_ID='ensure_people_table' AIRFLOW_CTX_EXECUTION_DATE='2025-04-01T00:00:00+00:00' AIRFLOW_CTX_TRY_NUMBER='1' AIRFLOW_CTX_DAG_RUN_ID='scheduled__2025-04-01T00:00:00+00:00'
[2025-04-02T16:08:27.127+0000] {people_dag.py:87} INFO - Attempting to connect to PostgreSQL...
[2025-04-02T16:08:27.145+0000] {people_dag.py:91} ERROR - Failed to ensure people table: The conn_id `postgres_default` isn't defined
[2025-04-02T16:08:27.161+0000] {taskinstance.py:2698} ERROR - Task failed with exception
Traceback (most recent call last):
  File "/opt/airflow/dags/people_dag.py", line 88, in ensure_people_table
    postgres_hook.run(CREATE_PEOPLE_TABLE_SQL)
  File "/home/airflow/.local/lib/python3.8/site-packages/airflow/providers/common/sql/hooks/sql.py", line 391, in run
    with closing(self.get_conn()) as conn:
  File "/home/airflow/.local/lib/python3.8/site-packages/airflow/providers/postgres/hooks/postgres.py", line 128, in get_conn
    conn = deepcopy(self.connection or self.get_connection(conn_id))
  File "/home/airflow/.local/lib/python3.8/site-packages/airflow/hooks/base.py", line 82, in get_connection
    conn = Connection.get_connection_from_secrets(conn_id)
  File "/home/airflow/.local/lib/python3.8/site-packages/airflow/models/connection.py", line 479, in get_connection_from_secrets
    raise AirflowNotFoundException(f"The conn_id `{conn_id}` isn't defined")
airflow.exceptions.AirflowNotFoundException: The conn_id `postgres_default` isn't defined

During handling of the above exception, another exception occurred:

Traceback (most recent call last):
  File "/home/airflow/.local/lib/python3.8/site-packages/airflow/models/taskinstance.py", line 433, in _execute_task
    result = execute_callable(context=context, **execute_callable_kwargs)
  File "/home/airflow/.local/lib/python3.8/site-packages/airflow/operators/python.py", line 199, in execute
    return_value = self.execute_callable()
  File "/home/airflow/.local/lib/python3.8/site-packages/airflow/operators/python.py", line 216, in execute_callable
    return self.python_callable(*self.op_args, **self.op_kwargs)
  File "/opt/airflow/dags/people_dag.py", line 92, in ensure_people_table
    raise AirflowException(f"Failed to ensure people table: {str(e)}")
airflow.exceptions.AirflowException: Failed to ensure people table: The conn_id `postgres_default` isn't defined
[2025-04-02T16:08:27.181+0000] {taskinstance.py:1138} INFO - Marking task as UP_FOR_RETRY. dag_id=People_Data_Pipeline, task_id=ensure_people_table, execution_date=20250401T000000, start_date=20250402T160826, end_date=20250402T160827
[2025-04-02T16:08:27.205+0000] {standard_task_runner.py:107} ERROR - Failed to execute job 2 for task ensure_people_table (Failed to ensure people table: The conn_id `postgres_default` isn't defined; 210)
[2025-04-02T16:08:27.243+0000] {local_task_job_runner.py:234} INFO - Task exited with return code 1
[2025-04-02T16:08:27.288+0000] {taskinstance.py:3280} INFO - 0 downstream tasks scheduled from follow-on schedule check
[2025-04-02T16:31:18.204+0000] {taskinstance.py:1956} INFO - Dependencies all met for dep_context=non-requeueable deps ti=<TaskInstance: People_Data_Pipeline.ensure_people_table scheduled__2025-04-01T00:00:00+00:00 [queued]>
[2025-04-02T16:31:18.215+0000] {taskinstance.py:1956} INFO - Dependencies all met for dep_context=requeueable deps ti=<TaskInstance: People_Data_Pipeline.ensure_people_table scheduled__2025-04-01T00:00:00+00:00 [queued]>
[2025-04-02T16:31:18.216+0000] {taskinstance.py:2170} INFO - Starting attempt 1 of 3
[2025-04-02T16:31:18.233+0000] {taskinstance.py:2191} INFO - Executing <Task(PythonOperator): ensure_people_table> on 2025-04-01 00:00:00+00:00
[2025-04-02T16:31:18.238+0000] {standard_task_runner.py:60} INFO - Started process 242 to run task
[2025-04-02T16:31:18.242+0000] {standard_task_runner.py:87} INFO - Running: ['***', 'tasks', 'run', 'People_Data_Pipeline', 'ensure_people_table', 'scheduled__2025-04-01T00:00:00+00:00', '--job-id', '3', '--raw', '--subdir', 'DAGS_FOLDER/people_dag.py', '--cfg-path', '/tmp/tmplrwp6s_v']
[2025-04-02T16:31:18.249+0000] {standard_task_runner.py:88} INFO - Job 3: Subtask ensure_people_table
[2025-04-02T16:31:18.312+0000] {task_command.py:423} INFO - Running <TaskInstance: People_Data_Pipeline.ensure_people_table scheduled__2025-04-01T00:00:00+00:00 [running]> on host e3653afa66c4
[2025-04-02T16:31:18.413+0000] {taskinstance.py:2480} INFO - Exporting env vars: AIRFLOW_CTX_DAG_OWNER='***' AIRFLOW_CTX_DAG_ID='People_Data_Pipeline' AIRFLOW_CTX_TASK_ID='ensure_people_table' AIRFLOW_CTX_EXECUTION_DATE='2025-04-01T00:00:00+00:00' AIRFLOW_CTX_TRY_NUMBER='1' AIRFLOW_CTX_DAG_RUN_ID='scheduled__2025-04-01T00:00:00+00:00'
[2025-04-02T16:31:18.416+0000] {people_dag.py:81} INFO - Attempting to connect to PostgreSQL...
[2025-04-02T16:31:18.429+0000] {people_dag.py:85} ERROR - Failed to ensure people table: The conn_id `postgres_default` isn't defined
[2025-04-02T16:31:18.441+0000] {taskinstance.py:2698} ERROR - Task failed with exception
Traceback (most recent call last):
  File "/opt/airflow/dags/people_dag.py", line 82, in ensure_people_table
    postgres_hook.run(CREATE_PEOPLE_TABLE_SQL)
  File "/home/airflow/.local/lib/python3.8/site-packages/airflow/providers/common/sql/hooks/sql.py", line 391, in run
    with closing(self.get_conn()) as conn:
  File "/home/airflow/.local/lib/python3.8/site-packages/airflow/providers/postgres/hooks/postgres.py", line 128, in get_conn
    conn = deepcopy(self.connection or self.get_connection(conn_id))
  File "/home/airflow/.local/lib/python3.8/site-packages/airflow/hooks/base.py", line 82, in get_connection
    conn = Connection.get_connection_from_secrets(conn_id)
  File "/home/airflow/.local/lib/python3.8/site-packages/airflow/models/connection.py", line 479, in get_connection_from_secrets
    raise AirflowNotFoundException(f"The conn_id `{conn_id}` isn't defined")
airflow.exceptions.AirflowNotFoundException: The conn_id `postgres_default` isn't defined

During handling of the above exception, another exception occurred:

Traceback (most recent call last):
  File "/home/airflow/.local/lib/python3.8/site-packages/airflow/models/taskinstance.py", line 433, in _execute_task
    result = execute_callable(context=context, **execute_callable_kwargs)
  File "/home/airflow/.local/lib/python3.8/site-packages/airflow/operators/python.py", line 199, in execute
    return_value = self.execute_callable()
  File "/home/airflow/.local/lib/python3.8/site-packages/airflow/operators/python.py", line 216, in execute_callable
    return self.python_callable(*self.op_args, **self.op_kwargs)
  File "/opt/airflow/dags/people_dag.py", line 86, in ensure_people_table
    raise AirflowException(f"Failed to ensure people table: {str(e)}")
airflow.exceptions.AirflowException: Failed to ensure people table: The conn_id `postgres_default` isn't defined
[2025-04-02T16:31:18.458+0000] {taskinstance.py:1138} INFO - Marking task as UP_FOR_RETRY. dag_id=People_Data_Pipeline, task_id=ensure_people_table, execution_date=20250401T000000, start_date=20250402T163118, end_date=20250402T163118
[2025-04-02T16:31:18.474+0000] {standard_task_runner.py:107} ERROR - Failed to execute job 3 for task ensure_people_table (Failed to ensure people table: The conn_id `postgres_default` isn't defined; 242)
[2025-04-02T16:31:18.496+0000] {local_task_job_runner.py:234} INFO - Task exited with return code 1
[2025-04-02T16:31:18.527+0000] {taskinstance.py:3280} INFO - 0 downstream tasks scheduled from follow-on schedule check
