[2025-04-02T15:36:03.149+0000] {taskinstance.py:1956} INFO - Dependencies all met for dep_context=non-requeueable deps ti=<TaskInstance: People_Data_Pipeline.ensure_people_table scheduled__2025-04-01T00:00:00+00:00 [queued]>
[2025-04-02T15:36:03.158+0000] {taskinstance.py:1956} INFO - Dependencies all met for dep_context=requeueable deps ti=<TaskInstance: People_Data_Pipeline.ensure_people_table scheduled__2025-04-01T00:00:00+00:00 [queued]>
[2025-04-02T15:36:03.159+0000] {taskinstance.py:2170} INFO - Starting attempt 3 of 3
[2025-04-02T15:36:03.179+0000] {taskinstance.py:2191} INFO - Executing <Task(PythonOperator): ensure_people_table> on 2025-04-01 00:00:00+00:00
[2025-04-02T15:36:03.185+0000] {standard_task_runner.py:60} INFO - Started process 702 to run task
[2025-04-02T15:36:03.191+0000] {standard_task_runner.py:87} INFO - Running: ['***', 'tasks', 'run', 'People_Data_Pipeline', 'ensure_people_table', 'scheduled__2025-04-01T00:00:00+00:00', '--job-id', '7', '--raw', '--subdir', 'DAGS_FOLDER/people_dag.py', '--cfg-path', '/tmp/tmpexl2efi7']
[2025-04-02T15:36:03.194+0000] {standard_task_runner.py:88} INFO - Job 7: Subtask ensure_people_table
[2025-04-02T15:36:03.263+0000] {task_command.py:423} INFO - Running <TaskInstance: People_Data_Pipeline.ensure_people_table scheduled__2025-04-01T00:00:00+00:00 [running]> on host decb7b281929
[2025-04-02T15:36:03.367+0000] {taskinstance.py:2480} INFO - Exporting env vars: AIRFLOW_CTX_DAG_OWNER='***' AIRFLOW_CTX_DAG_ID='People_Data_Pipeline' AIRFLOW_CTX_TASK_ID='ensure_people_table' AIRFLOW_CTX_EXECUTION_DATE='2025-04-01T00:00:00+00:00' AIRFLOW_CTX_TRY_NUMBER='3' AIRFLOW_CTX_DAG_RUN_ID='scheduled__2025-04-01T00:00:00+00:00'
[2025-04-02T15:36:03.386+0000] {taskinstance.py:2698} ERROR - Task failed with exception
Traceback (most recent call last):
  File "/home/airflow/.local/lib/python3.8/site-packages/airflow/models/taskinstance.py", line 433, in _execute_task
    result = execute_callable(context=context, **execute_callable_kwargs)
  File "/home/airflow/.local/lib/python3.8/site-packages/airflow/operators/python.py", line 199, in execute
    return_value = self.execute_callable()
  File "/home/airflow/.local/lib/python3.8/site-packages/airflow/operators/python.py", line 216, in execute_callable
    return self.python_callable(*self.op_args, **self.op_kwargs)
  File "/opt/airflow/dags/people_dag.py", line 85, in ensure_people_table
    postgres_hook.run(CREATE_PEOPLE_TABLE_SQL)
  File "/home/airflow/.local/lib/python3.8/site-packages/airflow/providers/common/sql/hooks/sql.py", line 391, in run
    with closing(self.get_conn()) as conn:
  File "/home/airflow/.local/lib/python3.8/site-packages/airflow/providers/postgres/hooks/postgres.py", line 128, in get_conn
    conn = deepcopy(self.connection or self.get_connection(conn_id))
  File "/home/airflow/.local/lib/python3.8/site-packages/airflow/hooks/base.py", line 82, in get_connection
    conn = Connection.get_connection_from_secrets(conn_id)
  File "/home/airflow/.local/lib/python3.8/site-packages/airflow/models/connection.py", line 479, in get_connection_from_secrets
    raise AirflowNotFoundException(f"The conn_id `{conn_id}` isn't defined")
airflow.exceptions.AirflowNotFoundException: The conn_id `postgres_default` isn't defined
[2025-04-02T15:36:03.397+0000] {taskinstance.py:1138} INFO - Marking task as FAILED. dag_id=People_Data_Pipeline, task_id=ensure_people_table, execution_date=20250401T000000, start_date=20250402T153603, end_date=20250402T153603
[2025-04-02T15:36:03.423+0000] {standard_task_runner.py:107} ERROR - Failed to execute job 7 for task ensure_people_table (The conn_id `postgres_default` isn't defined; 702)
[2025-04-02T15:36:03.443+0000] {local_task_job_runner.py:234} INFO - Task exited with return code 1
[2025-04-02T15:36:03.471+0000] {taskinstance.py:3280} INFO - 0 downstream tasks scheduled from follow-on schedule check
[2025-04-02T16:00:22.977+0000] {taskinstance.py:1956} INFO - Dependencies all met for dep_context=non-requeueable deps ti=<TaskInstance: People_Data_Pipeline.ensure_people_table scheduled__2025-04-01T00:00:00+00:00 [queued]>
[2025-04-02T16:00:22.998+0000] {taskinstance.py:1956} INFO - Dependencies all met for dep_context=requeueable deps ti=<TaskInstance: People_Data_Pipeline.ensure_people_table scheduled__2025-04-01T00:00:00+00:00 [queued]>
[2025-04-02T16:00:23.000+0000] {taskinstance.py:2170} INFO - Starting attempt 3 of 3
[2025-04-02T16:00:23.024+0000] {taskinstance.py:2191} INFO - Executing <Task(PythonOperator): ensure_people_table> on 2025-04-01 00:00:00+00:00
[2025-04-02T16:00:23.031+0000] {standard_task_runner.py:60} INFO - Started process 327 to run task
[2025-04-02T16:00:23.041+0000] {standard_task_runner.py:87} INFO - Running: ['***', 'tasks', 'run', 'People_Data_Pipeline', 'ensure_people_table', 'scheduled__2025-04-01T00:00:00+00:00', '--job-id', '7', '--raw', '--subdir', 'DAGS_FOLDER/people_dag.py', '--cfg-path', '/tmp/tmpg8x0vpvu']
[2025-04-02T16:00:23.046+0000] {standard_task_runner.py:88} INFO - Job 7: Subtask ensure_people_table
[2025-04-02T16:00:23.117+0000] {task_command.py:423} INFO - Running <TaskInstance: People_Data_Pipeline.ensure_people_table scheduled__2025-04-01T00:00:00+00:00 [running]> on host e8d989b91ca4
[2025-04-02T16:00:23.245+0000] {taskinstance.py:2480} INFO - Exporting env vars: AIRFLOW_CTX_DAG_OWNER='***' AIRFLOW_CTX_DAG_ID='People_Data_Pipeline' AIRFLOW_CTX_TASK_ID='ensure_people_table' AIRFLOW_CTX_EXECUTION_DATE='2025-04-01T00:00:00+00:00' AIRFLOW_CTX_TRY_NUMBER='3' AIRFLOW_CTX_DAG_RUN_ID='scheduled__2025-04-01T00:00:00+00:00'
[2025-04-02T16:00:23.247+0000] {people_dag.py:87} INFO - Attempting to connect to PostgreSQL...
[2025-04-02T16:00:23.257+0000] {people_dag.py:91} ERROR - Failed to ensure people table: The conn_id `postgres_default` isn't defined
[2025-04-02T16:00:23.267+0000] {taskinstance.py:2698} ERROR - Task failed with exception
Traceback (most recent call last):
  File "/opt/airflow/dags/people_dag.py", line 88, in ensure_people_table
    postgres_hook.run(CREATE_PEOPLE_TABLE_SQL)
  File "/home/airflow/.local/lib/python3.8/site-packages/airflow/providers/common/sql/hooks/sql.py", line 391, in run
    with closing(self.get_conn()) as conn:
  File "/home/airflow/.local/lib/python3.8/site-packages/airflow/providers/postgres/hooks/postgres.py", line 128, in get_conn
    conn = deepcopy(self.connection or self.get_connection(conn_id))
  File "/home/airflow/.local/lib/python3.8/site-packages/airflow/hooks/base.py", line 82, in get_connection
    conn = Connection.get_connection_from_secrets(conn_id)
  File "/home/airflow/.local/lib/python3.8/site-packages/airflow/models/connection.py", line 479, in get_connection_from_secrets
    raise AirflowNotFoundException(f"The conn_id `{conn_id}` isn't defined")
airflow.exceptions.AirflowNotFoundException: The conn_id `postgres_default` isn't defined

During handling of the above exception, another exception occurred:

Traceback (most recent call last):
  File "/home/airflow/.local/lib/python3.8/site-packages/airflow/models/taskinstance.py", line 433, in _execute_task
    result = execute_callable(context=context, **execute_callable_kwargs)
  File "/home/airflow/.local/lib/python3.8/site-packages/airflow/operators/python.py", line 199, in execute
    return_value = self.execute_callable()
  File "/home/airflow/.local/lib/python3.8/site-packages/airflow/operators/python.py", line 216, in execute_callable
    return self.python_callable(*self.op_args, **self.op_kwargs)
  File "/opt/airflow/dags/people_dag.py", line 92, in ensure_people_table
    raise AirflowException(f"Failed to ensure people table: {str(e)}")
airflow.exceptions.AirflowException: Failed to ensure people table: The conn_id `postgres_default` isn't defined
[2025-04-02T16:00:23.283+0000] {taskinstance.py:1138} INFO - Marking task as FAILED. dag_id=People_Data_Pipeline, task_id=ensure_people_table, execution_date=20250401T000000, start_date=20250402T160022, end_date=20250402T160023
[2025-04-02T16:00:23.297+0000] {standard_task_runner.py:107} ERROR - Failed to execute job 7 for task ensure_people_table (Failed to ensure people table: The conn_id `postgres_default` isn't defined; 327)
[2025-04-02T16:00:23.333+0000] {local_task_job_runner.py:234} INFO - Task exited with return code 1
[2025-04-02T16:00:23.364+0000] {taskinstance.py:3280} INFO - 0 downstream tasks scheduled from follow-on schedule check
[2025-04-02T16:15:39.018+0000] {taskinstance.py:1956} INFO - Dependencies all met for dep_context=non-requeueable deps ti=<TaskInstance: People_Data_Pipeline.ensure_people_table scheduled__2025-04-01T00:00:00+00:00 [queued]>
[2025-04-02T16:15:39.034+0000] {taskinstance.py:1956} INFO - Dependencies all met for dep_context=requeueable deps ti=<TaskInstance: People_Data_Pipeline.ensure_people_table scheduled__2025-04-01T00:00:00+00:00 [queued]>
[2025-04-02T16:15:39.035+0000] {taskinstance.py:2170} INFO - Starting attempt 3 of 3
[2025-04-02T16:15:39.056+0000] {taskinstance.py:2191} INFO - Executing <Task(PythonOperator): ensure_people_table> on 2025-04-01 00:00:00+00:00
[2025-04-02T16:15:39.062+0000] {standard_task_runner.py:60} INFO - Started process 366 to run task
[2025-04-02T16:15:39.066+0000] {standard_task_runner.py:87} INFO - Running: ['***', 'tasks', 'run', 'People_Data_Pipeline', 'ensure_people_table', 'scheduled__2025-04-01T00:00:00+00:00', '--job-id', '7', '--raw', '--subdir', 'DAGS_FOLDER/people_dag.py', '--cfg-path', '/tmp/tmpbgaikhln']
[2025-04-02T16:15:39.070+0000] {standard_task_runner.py:88} INFO - Job 7: Subtask ensure_people_table
[2025-04-02T16:15:39.136+0000] {task_command.py:423} INFO - Running <TaskInstance: People_Data_Pipeline.ensure_people_table scheduled__2025-04-01T00:00:00+00:00 [running]> on host 4c976e0a7b20
[2025-04-02T16:15:39.241+0000] {taskinstance.py:2480} INFO - Exporting env vars: AIRFLOW_CTX_DAG_OWNER='***' AIRFLOW_CTX_DAG_ID='People_Data_Pipeline' AIRFLOW_CTX_TASK_ID='ensure_people_table' AIRFLOW_CTX_EXECUTION_DATE='2025-04-01T00:00:00+00:00' AIRFLOW_CTX_TRY_NUMBER='3' AIRFLOW_CTX_DAG_RUN_ID='scheduled__2025-04-01T00:00:00+00:00'
[2025-04-02T16:15:39.243+0000] {people_dag.py:87} INFO - Attempting to connect to PostgreSQL...
[2025-04-02T16:15:39.261+0000] {base.py:83} INFO - Using connection ID 'postgres_default' for task execution.
[2025-04-02T16:15:39.262+0000] {people_dag.py:91} ERROR - Failed to ensure people table: could not translate host name "localhost:8081" to address: Name or service not known

[2025-04-02T16:15:39.272+0000] {taskinstance.py:2698} ERROR - Task failed with exception
Traceback (most recent call last):
  File "/opt/airflow/dags/people_dag.py", line 88, in ensure_people_table
    postgres_hook.run(CREATE_PEOPLE_TABLE_SQL)
  File "/home/airflow/.local/lib/python3.8/site-packages/airflow/providers/common/sql/hooks/sql.py", line 391, in run
    with closing(self.get_conn()) as conn:
  File "/home/airflow/.local/lib/python3.8/site-packages/airflow/providers/postgres/hooks/postgres.py", line 158, in get_conn
    self.conn = psycopg2.connect(**conn_args)
  File "/home/airflow/.local/lib/python3.8/site-packages/psycopg2/__init__.py", line 122, in connect
    conn = _connect(dsn, connection_factory=connection_factory, **kwasync)
psycopg2.OperationalError: could not translate host name "localhost:8081" to address: Name or service not known


During handling of the above exception, another exception occurred:

Traceback (most recent call last):
  File "/home/airflow/.local/lib/python3.8/site-packages/airflow/models/taskinstance.py", line 433, in _execute_task
    result = execute_callable(context=context, **execute_callable_kwargs)
  File "/home/airflow/.local/lib/python3.8/site-packages/airflow/operators/python.py", line 199, in execute
    return_value = self.execute_callable()
  File "/home/airflow/.local/lib/python3.8/site-packages/airflow/operators/python.py", line 216, in execute_callable
    return self.python_callable(*self.op_args, **self.op_kwargs)
  File "/opt/airflow/dags/people_dag.py", line 92, in ensure_people_table
    raise AirflowException(f"Failed to ensure people table: {str(e)}")
airflow.exceptions.AirflowException: Failed to ensure people table: could not translate host name "localhost:8081" to address: Name or service not known

[2025-04-02T16:15:39.281+0000] {taskinstance.py:1138} INFO - Marking task as FAILED. dag_id=People_Data_Pipeline, task_id=ensure_people_table, execution_date=20250401T000000, start_date=20250402T161539, end_date=20250402T161539
[2025-04-02T16:15:39.296+0000] {standard_task_runner.py:107} ERROR - Failed to execute job 7 for task ensure_people_table (Failed to ensure people table: could not translate host name "localhost:8081" to address: Name or service not known
; 366)
[2025-04-02T16:15:39.319+0000] {local_task_job_runner.py:234} INFO - Task exited with return code 1
[2025-04-02T16:15:39.346+0000] {taskinstance.py:3280} INFO - 0 downstream tasks scheduled from follow-on schedule check
[2025-04-02T16:37:20.201+0000] {taskinstance.py:1956} INFO - Dependencies all met for dep_context=non-requeueable deps ti=<TaskInstance: People_Data_Pipeline.ensure_people_table scheduled__2025-04-01T00:00:00+00:00 [queued]>
[2025-04-02T16:37:20.214+0000] {taskinstance.py:1956} INFO - Dependencies all met for dep_context=requeueable deps ti=<TaskInstance: People_Data_Pipeline.ensure_people_table scheduled__2025-04-01T00:00:00+00:00 [queued]>
[2025-04-02T16:37:20.215+0000] {taskinstance.py:2170} INFO - Starting attempt 3 of 3
[2025-04-02T16:37:20.236+0000] {taskinstance.py:2191} INFO - Executing <Task(PythonOperator): ensure_people_table> on 2025-04-01 00:00:00+00:00
[2025-04-02T16:37:20.241+0000] {standard_task_runner.py:60} INFO - Started process 366 to run task
[2025-04-02T16:37:20.247+0000] {standard_task_runner.py:87} INFO - Running: ['***', 'tasks', 'run', 'People_Data_Pipeline', 'ensure_people_table', 'scheduled__2025-04-01T00:00:00+00:00', '--job-id', '5', '--raw', '--subdir', 'DAGS_FOLDER/people_dag.py', '--cfg-path', '/tmp/tmp3xkro77i']
[2025-04-02T16:37:20.251+0000] {standard_task_runner.py:88} INFO - Job 5: Subtask ensure_people_table
[2025-04-02T16:37:20.314+0000] {task_command.py:423} INFO - Running <TaskInstance: People_Data_Pipeline.ensure_people_table scheduled__2025-04-01T00:00:00+00:00 [running]> on host e3653afa66c4
[2025-04-02T16:37:20.400+0000] {taskinstance.py:2480} INFO - Exporting env vars: AIRFLOW_CTX_DAG_OWNER='***' AIRFLOW_CTX_DAG_ID='People_Data_Pipeline' AIRFLOW_CTX_TASK_ID='ensure_people_table' AIRFLOW_CTX_EXECUTION_DATE='2025-04-01T00:00:00+00:00' AIRFLOW_CTX_TRY_NUMBER='3' AIRFLOW_CTX_DAG_RUN_ID='scheduled__2025-04-01T00:00:00+00:00'
[2025-04-02T16:37:20.402+0000] {people_dag.py:81} INFO - Attempting to connect to PostgreSQL...
[2025-04-02T16:37:20.414+0000] {people_dag.py:85} ERROR - Failed to ensure people table: The conn_id `postgres_default` isn't defined
[2025-04-02T16:37:20.425+0000] {taskinstance.py:2698} ERROR - Task failed with exception
Traceback (most recent call last):
  File "/opt/airflow/dags/people_dag.py", line 82, in ensure_people_table
    postgres_hook.run(CREATE_PEOPLE_TABLE_SQL)
  File "/home/airflow/.local/lib/python3.8/site-packages/airflow/providers/common/sql/hooks/sql.py", line 391, in run
    with closing(self.get_conn()) as conn:
  File "/home/airflow/.local/lib/python3.8/site-packages/airflow/providers/postgres/hooks/postgres.py", line 128, in get_conn
    conn = deepcopy(self.connection or self.get_connection(conn_id))
  File "/home/airflow/.local/lib/python3.8/site-packages/airflow/hooks/base.py", line 82, in get_connection
    conn = Connection.get_connection_from_secrets(conn_id)
  File "/home/airflow/.local/lib/python3.8/site-packages/airflow/models/connection.py", line 479, in get_connection_from_secrets
    raise AirflowNotFoundException(f"The conn_id `{conn_id}` isn't defined")
airflow.exceptions.AirflowNotFoundException: The conn_id `postgres_default` isn't defined

During handling of the above exception, another exception occurred:

Traceback (most recent call last):
  File "/home/airflow/.local/lib/python3.8/site-packages/airflow/models/taskinstance.py", line 433, in _execute_task
    result = execute_callable(context=context, **execute_callable_kwargs)
  File "/home/airflow/.local/lib/python3.8/site-packages/airflow/operators/python.py", line 199, in execute
    return_value = self.execute_callable()
  File "/home/airflow/.local/lib/python3.8/site-packages/airflow/operators/python.py", line 216, in execute_callable
    return self.python_callable(*self.op_args, **self.op_kwargs)
  File "/opt/airflow/dags/people_dag.py", line 86, in ensure_people_table
    raise AirflowException(f"Failed to ensure people table: {str(e)}")
airflow.exceptions.AirflowException: Failed to ensure people table: The conn_id `postgres_default` isn't defined
[2025-04-02T16:37:20.439+0000] {taskinstance.py:1138} INFO - Marking task as FAILED. dag_id=People_Data_Pipeline, task_id=ensure_people_table, execution_date=20250401T000000, start_date=20250402T163720, end_date=20250402T163720
[2025-04-02T16:37:20.457+0000] {standard_task_runner.py:107} ERROR - Failed to execute job 5 for task ensure_people_table (Failed to ensure people table: The conn_id `postgres_default` isn't defined; 366)
[2025-04-02T16:37:20.501+0000] {local_task_job_runner.py:234} INFO - Task exited with return code 1
[2025-04-02T16:37:20.536+0000] {taskinstance.py:3280} INFO - 0 downstream tasks scheduled from follow-on schedule check
