[2025-04-03T10:41:52.613+0000] {taskinstance.py:1956} INFO - Dependencies all met for dep_context=non-requeueable deps ti=<TaskInstance: Web_Log_Processing.generate_analytics_report scheduled__2025-04-02T00:00:00+00:00 [queued]>
[2025-04-03T10:41:52.626+0000] {taskinstance.py:1956} INFO - Dependencies all met for dep_context=requeueable deps ti=<TaskInstance: Web_Log_Processing.generate_analytics_report scheduled__2025-04-02T00:00:00+00:00 [queued]>
[2025-04-03T10:41:52.627+0000] {taskinstance.py:2170} INFO - Starting attempt 3 of 4
[2025-04-03T10:41:52.644+0000] {taskinstance.py:2191} INFO - Executing <Task(BashOperator): generate_analytics_report> on 2025-04-02 00:00:00+00:00
[2025-04-03T10:41:52.650+0000] {standard_task_runner.py:60} INFO - Started process 423 to run task
[2025-04-03T10:41:52.656+0000] {standard_task_runner.py:87} INFO - Running: ['***', 'tasks', 'run', 'Web_Log_Processing', 'generate_analytics_report', 'scheduled__2025-04-02T00:00:00+00:00', '--job-id', '5', '--raw', '--subdir', 'DAGS_FOLDER/w3c.py', '--cfg-path', '/tmp/tmpahtgsydc']
[2025-04-03T10:41:52.660+0000] {standard_task_runner.py:88} INFO - Job 5: Subtask generate_analytics_report
[2025-04-03T10:41:52.724+0000] {task_command.py:423} INFO - Running <TaskInstance: Web_Log_Processing.generate_analytics_report scheduled__2025-04-02T00:00:00+00:00 [running]> on host c4002c286bfc
[2025-04-03T10:41:53.011+0000] {taskinstance.py:2480} INFO - Exporting env vars: AIRFLOW_CTX_DAG_OWNER='***' AIRFLOW_CTX_DAG_ID='Web_Log_Processing' AIRFLOW_CTX_TASK_ID='generate_analytics_report' AIRFLOW_CTX_EXECUTION_DATE='2025-04-02T00:00:00+00:00' AIRFLOW_CTX_TRY_NUMBER='3' AIRFLOW_CTX_DAG_RUN_ID='scheduled__2025-04-02T00:00:00+00:00'
[2025-04-03T10:41:53.022+0000] {subprocess.py:63} INFO - Tmp dir root location: /tmp
[2025-04-03T10:41:53.026+0000] {subprocess.py:75} INFO - Running command: ['/usr/bin/bash', '-c', 'python /opt/***/dags/analytics.py']
[2025-04-03T10:41:53.051+0000] {subprocess.py:86} INFO - Output:
[2025-04-03T10:41:53.086+0000] {subprocess.py:93} INFO - python: can't open file '/opt/***/dags/analytics.py': [Errno 2] No such file or directory
[2025-04-03T10:41:53.089+0000] {subprocess.py:97} INFO - Command exited with return code 2
[2025-04-03T10:41:53.102+0000] {taskinstance.py:2698} ERROR - Task failed with exception
Traceback (most recent call last):
  File "/home/airflow/.local/lib/python3.8/site-packages/airflow/models/taskinstance.py", line 433, in _execute_task
    result = execute_callable(context=context, **execute_callable_kwargs)
  File "/home/airflow/.local/lib/python3.8/site-packages/airflow/operators/bash.py", line 212, in execute
    raise AirflowException(
airflow.exceptions.AirflowException: Bash command failed. The command returned a non-zero exit code 2.
[2025-04-03T10:41:53.108+0000] {taskinstance.py:1138} INFO - Marking task as UP_FOR_RETRY. dag_id=Web_Log_Processing, task_id=generate_analytics_report, execution_date=20250402T000000, start_date=20250403T104152, end_date=20250403T104153
[2025-04-03T10:41:53.124+0000] {standard_task_runner.py:107} ERROR - Failed to execute job 5 for task generate_analytics_report (Bash command failed. The command returned a non-zero exit code 2.; 423)
[2025-04-03T10:41:53.150+0000] {local_task_job_runner.py:234} INFO - Task exited with return code 1
[2025-04-03T10:41:53.169+0000] {taskinstance.py:3280} INFO - 0 downstream tasks scheduled from follow-on schedule check
