[2025-04-03T10:36:50.936+0000] {taskinstance.py:1956} INFO - Dependencies all met for dep_context=non-requeueable deps ti=<TaskInstance: Web_Log_Processing.generate_analytics_report scheduled__2025-04-02T00:00:00+00:00 [queued]>
[2025-04-03T10:36:50.946+0000] {taskinstance.py:1956} INFO - Dependencies all met for dep_context=requeueable deps ti=<TaskInstance: Web_Log_Processing.generate_analytics_report scheduled__2025-04-02T00:00:00+00:00 [queued]>
[2025-04-03T10:36:50.947+0000] {taskinstance.py:2170} INFO - Starting attempt 2 of 4
[2025-04-03T10:36:50.962+0000] {taskinstance.py:2191} INFO - Executing <Task(BashOperator): generate_analytics_report> on 2025-04-02 00:00:00+00:00
[2025-04-03T10:36:50.968+0000] {standard_task_runner.py:60} INFO - Started process 309 to run task
[2025-04-03T10:36:50.973+0000] {standard_task_runner.py:87} INFO - Running: ['***', 'tasks', 'run', 'Web_Log_Processing', 'generate_analytics_report', 'scheduled__2025-04-02T00:00:00+00:00', '--job-id', '4', '--raw', '--subdir', 'DAGS_FOLDER/w3c.py', '--cfg-path', '/tmp/tmpo3n7imy2']
[2025-04-03T10:36:50.976+0000] {standard_task_runner.py:88} INFO - Job 4: Subtask generate_analytics_report
[2025-04-03T10:36:51.044+0000] {task_command.py:423} INFO - Running <TaskInstance: Web_Log_Processing.generate_analytics_report scheduled__2025-04-02T00:00:00+00:00 [running]> on host c4002c286bfc
[2025-04-03T10:36:51.336+0000] {taskinstance.py:2480} INFO - Exporting env vars: AIRFLOW_CTX_DAG_OWNER='***' AIRFLOW_CTX_DAG_ID='Web_Log_Processing' AIRFLOW_CTX_TASK_ID='generate_analytics_report' AIRFLOW_CTX_EXECUTION_DATE='2025-04-02T00:00:00+00:00' AIRFLOW_CTX_TRY_NUMBER='2' AIRFLOW_CTX_DAG_RUN_ID='scheduled__2025-04-02T00:00:00+00:00'
[2025-04-03T10:36:51.339+0000] {subprocess.py:63} INFO - Tmp dir root location: /tmp
[2025-04-03T10:36:51.340+0000] {subprocess.py:75} INFO - Running command: ['/usr/bin/bash', '-c', 'python /opt/***/dags/analytics.py']
[2025-04-03T10:36:51.351+0000] {subprocess.py:86} INFO - Output:
[2025-04-03T10:36:51.379+0000] {subprocess.py:93} INFO - python: can't open file '/opt/***/dags/analytics.py': [Errno 2] No such file or directory
[2025-04-03T10:36:51.382+0000] {subprocess.py:97} INFO - Command exited with return code 2
[2025-04-03T10:36:51.393+0000] {taskinstance.py:2698} ERROR - Task failed with exception
Traceback (most recent call last):
  File "/home/airflow/.local/lib/python3.8/site-packages/airflow/models/taskinstance.py", line 433, in _execute_task
    result = execute_callable(context=context, **execute_callable_kwargs)
  File "/home/airflow/.local/lib/python3.8/site-packages/airflow/operators/bash.py", line 212, in execute
    raise AirflowException(
airflow.exceptions.AirflowException: Bash command failed. The command returned a non-zero exit code 2.
[2025-04-03T10:36:51.398+0000] {taskinstance.py:1138} INFO - Marking task as UP_FOR_RETRY. dag_id=Web_Log_Processing, task_id=generate_analytics_report, execution_date=20250402T000000, start_date=20250403T103650, end_date=20250403T103651
[2025-04-03T10:36:51.415+0000] {standard_task_runner.py:107} ERROR - Failed to execute job 4 for task generate_analytics_report (Bash command failed. The command returned a non-zero exit code 2.; 309)
[2025-04-03T10:36:51.467+0000] {local_task_job_runner.py:234} INFO - Task exited with return code 1
[2025-04-03T10:36:51.498+0000] {taskinstance.py:3280} INFO - 0 downstream tasks scheduled from follow-on schedule check
