[2025-04-03T10:29:45.675+0000] {taskinstance.py:1956} INFO - Dependencies all met for dep_context=non-requeueable deps ti=<TaskInstance: Web_Log_Processing.generate_analytics_report scheduled__2025-04-02T00:00:00+00:00 [queued]>
[2025-04-03T10:29:45.686+0000] {taskinstance.py:1956} INFO - Dependencies all met for dep_context=requeueable deps ti=<TaskInstance: Web_Log_Processing.generate_analytics_report scheduled__2025-04-02T00:00:00+00:00 [queued]>
[2025-04-03T10:29:45.687+0000] {taskinstance.py:2170} INFO - Starting attempt 1 of 4
[2025-04-03T10:29:45.705+0000] {taskinstance.py:2191} INFO - Executing <Task(BashOperator): generate_analytics_report> on 2025-04-02 00:00:00+00:00
[2025-04-03T10:29:45.712+0000] {standard_task_runner.py:60} INFO - Started process 385 to run task
[2025-04-03T10:29:45.717+0000] {standard_task_runner.py:87} INFO - Running: ['***', 'tasks', 'run', 'Web_Log_Processing', 'generate_analytics_report', 'scheduled__2025-04-02T00:00:00+00:00', '--job-id', '4', '--raw', '--subdir', 'DAGS_FOLDER/w3c.py', '--cfg-path', '/tmp/tmpqetuz_ar']
[2025-04-03T10:29:45.720+0000] {standard_task_runner.py:88} INFO - Job 4: Subtask generate_analytics_report
[2025-04-03T10:29:45.784+0000] {task_command.py:423} INFO - Running <TaskInstance: Web_Log_Processing.generate_analytics_report scheduled__2025-04-02T00:00:00+00:00 [running]> on host a086d075ccfe
[2025-04-03T10:29:46.057+0000] {taskinstance.py:2480} INFO - Exporting env vars: AIRFLOW_CTX_DAG_OWNER='***' AIRFLOW_CTX_DAG_ID='Web_Log_Processing' AIRFLOW_CTX_TASK_ID='generate_analytics_report' AIRFLOW_CTX_EXECUTION_DATE='2025-04-02T00:00:00+00:00' AIRFLOW_CTX_TRY_NUMBER='1' AIRFLOW_CTX_DAG_RUN_ID='scheduled__2025-04-02T00:00:00+00:00'
[2025-04-03T10:29:46.060+0000] {subprocess.py:63} INFO - Tmp dir root location: /tmp
[2025-04-03T10:29:46.062+0000] {subprocess.py:75} INFO - Running command: ['/usr/bin/bash', '-c', 'python /opt/***/dags/analytics.py']
[2025-04-03T10:29:46.073+0000] {subprocess.py:86} INFO - Output:
[2025-04-03T10:29:46.108+0000] {subprocess.py:93} INFO - python: can't open file '/opt/***/dags/analytics.py': [Errno 2] No such file or directory
[2025-04-03T10:29:46.111+0000] {subprocess.py:97} INFO - Command exited with return code 2
[2025-04-03T10:29:46.123+0000] {taskinstance.py:2698} ERROR - Task failed with exception
Traceback (most recent call last):
  File "/home/airflow/.local/lib/python3.8/site-packages/airflow/models/taskinstance.py", line 433, in _execute_task
    result = execute_callable(context=context, **execute_callable_kwargs)
  File "/home/airflow/.local/lib/python3.8/site-packages/airflow/operators/bash.py", line 212, in execute
    raise AirflowException(
airflow.exceptions.AirflowException: Bash command failed. The command returned a non-zero exit code 2.
[2025-04-03T10:29:46.127+0000] {taskinstance.py:1138} INFO - Marking task as UP_FOR_RETRY. dag_id=Web_Log_Processing, task_id=generate_analytics_report, execution_date=20250402T000000, start_date=20250403T102945, end_date=20250403T102946
[2025-04-03T10:29:46.146+0000] {standard_task_runner.py:107} ERROR - Failed to execute job 4 for task generate_analytics_report (Bash command failed. The command returned a non-zero exit code 2.; 385)
[2025-04-03T10:29:46.171+0000] {local_task_job_runner.py:234} INFO - Task exited with return code 1
[2025-04-03T10:29:46.189+0000] {taskinstance.py:3280} INFO - 0 downstream tasks scheduled from follow-on schedule check
[2025-04-03T10:31:49.722+0000] {taskinstance.py:1956} INFO - Dependencies all met for dep_context=non-requeueable deps ti=<TaskInstance: Web_Log_Processing.generate_analytics_report scheduled__2025-04-02T00:00:00+00:00 [queued]>
[2025-04-03T10:31:49.733+0000] {taskinstance.py:1956} INFO - Dependencies all met for dep_context=requeueable deps ti=<TaskInstance: Web_Log_Processing.generate_analytics_report scheduled__2025-04-02T00:00:00+00:00 [queued]>
[2025-04-03T10:31:49.734+0000] {taskinstance.py:2170} INFO - Starting attempt 1 of 4
[2025-04-03T10:31:49.752+0000] {taskinstance.py:2191} INFO - Executing <Task(BashOperator): generate_analytics_report> on 2025-04-02 00:00:00+00:00
[2025-04-03T10:31:49.757+0000] {standard_task_runner.py:60} INFO - Started process 195 to run task
[2025-04-03T10:31:49.763+0000] {standard_task_runner.py:87} INFO - Running: ['***', 'tasks', 'run', 'Web_Log_Processing', 'generate_analytics_report', 'scheduled__2025-04-02T00:00:00+00:00', '--job-id', '3', '--raw', '--subdir', 'DAGS_FOLDER/w3c.py', '--cfg-path', '/tmp/tmpb_zqj9to']
[2025-04-03T10:31:49.766+0000] {standard_task_runner.py:88} INFO - Job 3: Subtask generate_analytics_report
[2025-04-03T10:31:49.839+0000] {task_command.py:423} INFO - Running <TaskInstance: Web_Log_Processing.generate_analytics_report scheduled__2025-04-02T00:00:00+00:00 [running]> on host c4002c286bfc
[2025-04-03T10:31:50.124+0000] {taskinstance.py:2480} INFO - Exporting env vars: AIRFLOW_CTX_DAG_OWNER='***' AIRFLOW_CTX_DAG_ID='Web_Log_Processing' AIRFLOW_CTX_TASK_ID='generate_analytics_report' AIRFLOW_CTX_EXECUTION_DATE='2025-04-02T00:00:00+00:00' AIRFLOW_CTX_TRY_NUMBER='1' AIRFLOW_CTX_DAG_RUN_ID='scheduled__2025-04-02T00:00:00+00:00'
[2025-04-03T10:31:50.127+0000] {subprocess.py:63} INFO - Tmp dir root location: /tmp
[2025-04-03T10:31:50.128+0000] {subprocess.py:75} INFO - Running command: ['/usr/bin/bash', '-c', 'python /opt/***/dags/analytics.py']
[2025-04-03T10:31:50.137+0000] {subprocess.py:86} INFO - Output:
[2025-04-03T10:31:50.168+0000] {subprocess.py:93} INFO - python: can't open file '/opt/***/dags/analytics.py': [Errno 2] No such file or directory
[2025-04-03T10:31:50.171+0000] {subprocess.py:97} INFO - Command exited with return code 2
[2025-04-03T10:31:50.183+0000] {taskinstance.py:2698} ERROR - Task failed with exception
Traceback (most recent call last):
  File "/home/airflow/.local/lib/python3.8/site-packages/airflow/models/taskinstance.py", line 433, in _execute_task
    result = execute_callable(context=context, **execute_callable_kwargs)
  File "/home/airflow/.local/lib/python3.8/site-packages/airflow/operators/bash.py", line 212, in execute
    raise AirflowException(
airflow.exceptions.AirflowException: Bash command failed. The command returned a non-zero exit code 2.
[2025-04-03T10:31:50.187+0000] {taskinstance.py:1138} INFO - Marking task as UP_FOR_RETRY. dag_id=Web_Log_Processing, task_id=generate_analytics_report, execution_date=20250402T000000, start_date=20250403T103149, end_date=20250403T103150
[2025-04-03T10:31:50.202+0000] {standard_task_runner.py:107} ERROR - Failed to execute job 3 for task generate_analytics_report (Bash command failed. The command returned a non-zero exit code 2.; 195)
[2025-04-03T10:31:50.217+0000] {local_task_job_runner.py:234} INFO - Task exited with return code 1
[2025-04-03T10:31:50.253+0000] {taskinstance.py:3280} INFO - 0 downstream tasks scheduled from follow-on schedule check
[2025-04-03T10:53:10.600+0000] {taskinstance.py:1956} INFO - Dependencies all met for dep_context=non-requeueable deps ti=<TaskInstance: Web_Log_Processing.generate_analytics_report scheduled__2025-04-02T00:00:00+00:00 [queued]>
[2025-04-03T10:53:10.615+0000] {taskinstance.py:1956} INFO - Dependencies all met for dep_context=requeueable deps ti=<TaskInstance: Web_Log_Processing.generate_analytics_report scheduled__2025-04-02T00:00:00+00:00 [queued]>
[2025-04-03T10:53:10.616+0000] {taskinstance.py:2170} INFO - Starting attempt 1 of 4
[2025-04-03T10:53:10.641+0000] {taskinstance.py:2191} INFO - Executing <Task(BashOperator): generate_analytics_report> on 2025-04-02 00:00:00+00:00
[2025-04-03T10:53:10.649+0000] {standard_task_runner.py:60} INFO - Started process 387 to run task
[2025-04-03T10:53:10.653+0000] {standard_task_runner.py:87} INFO - Running: ['***', 'tasks', 'run', 'Web_Log_Processing', 'generate_analytics_report', 'scheduled__2025-04-02T00:00:00+00:00', '--job-id', '3', '--raw', '--subdir', 'DAGS_FOLDER/w3c.py', '--cfg-path', '/tmp/tmp9ojx9sgl']
[2025-04-03T10:53:10.656+0000] {standard_task_runner.py:88} INFO - Job 3: Subtask generate_analytics_report
[2025-04-03T10:53:10.736+0000] {task_command.py:423} INFO - Running <TaskInstance: Web_Log_Processing.generate_analytics_report scheduled__2025-04-02T00:00:00+00:00 [running]> on host 5720a5f2ee39
[2025-04-03T10:53:11.023+0000] {taskinstance.py:2480} INFO - Exporting env vars: AIRFLOW_CTX_DAG_OWNER='***' AIRFLOW_CTX_DAG_ID='Web_Log_Processing' AIRFLOW_CTX_TASK_ID='generate_analytics_report' AIRFLOW_CTX_EXECUTION_DATE='2025-04-02T00:00:00+00:00' AIRFLOW_CTX_TRY_NUMBER='1' AIRFLOW_CTX_DAG_RUN_ID='scheduled__2025-04-02T00:00:00+00:00'
[2025-04-03T10:53:11.024+0000] {subprocess.py:63} INFO - Tmp dir root location: /tmp
[2025-04-03T10:53:11.025+0000] {subprocess.py:75} INFO - Running command: ['/usr/bin/bash', '-c', 'python /opt/***/dags/analytics.py']
[2025-04-03T10:53:11.037+0000] {subprocess.py:86} INFO - Output:
[2025-04-03T10:53:11.071+0000] {subprocess.py:93} INFO - python: can't open file '/opt/***/dags/analytics.py': [Errno 2] No such file or directory
[2025-04-03T10:53:11.074+0000] {subprocess.py:97} INFO - Command exited with return code 2
[2025-04-03T10:53:11.086+0000] {taskinstance.py:2698} ERROR - Task failed with exception
Traceback (most recent call last):
  File "/home/airflow/.local/lib/python3.8/site-packages/airflow/models/taskinstance.py", line 433, in _execute_task
    result = execute_callable(context=context, **execute_callable_kwargs)
  File "/home/airflow/.local/lib/python3.8/site-packages/airflow/operators/bash.py", line 212, in execute
    raise AirflowException(
airflow.exceptions.AirflowException: Bash command failed. The command returned a non-zero exit code 2.
[2025-04-03T10:53:11.090+0000] {taskinstance.py:1138} INFO - Marking task as UP_FOR_RETRY. dag_id=Web_Log_Processing, task_id=generate_analytics_report, execution_date=20250402T000000, start_date=20250403T105310, end_date=20250403T105311
[2025-04-03T10:53:11.120+0000] {standard_task_runner.py:107} ERROR - Failed to execute job 3 for task generate_analytics_report (Bash command failed. The command returned a non-zero exit code 2.; 387)
[2025-04-03T10:53:11.147+0000] {local_task_job_runner.py:234} INFO - Task exited with return code 1
[2025-04-03T10:53:11.164+0000] {taskinstance.py:3280} INFO - 0 downstream tasks scheduled from follow-on schedule check
[2025-04-03T14:24:03.553+0000] {taskinstance.py:1956} INFO - Dependencies all met for dep_context=non-requeueable deps ti=<TaskInstance: Web_Log_Processing.generate_analytics_report scheduled__2025-04-02T00:00:00+00:00 [queued]>
[2025-04-03T14:24:03.563+0000] {taskinstance.py:1956} INFO - Dependencies all met for dep_context=requeueable deps ti=<TaskInstance: Web_Log_Processing.generate_analytics_report scheduled__2025-04-02T00:00:00+00:00 [queued]>
[2025-04-03T14:24:03.564+0000] {taskinstance.py:2170} INFO - Starting attempt 1 of 4
[2025-04-03T14:24:03.579+0000] {taskinstance.py:2191} INFO - Executing <Task(BashOperator): generate_analytics_report> on 2025-04-02 00:00:00+00:00
[2025-04-03T14:24:03.584+0000] {standard_task_runner.py:60} INFO - Started process 342 to run task
[2025-04-03T14:24:03.588+0000] {standard_task_runner.py:87} INFO - Running: ['***', 'tasks', 'run', 'Web_Log_Processing', 'generate_analytics_report', 'scheduled__2025-04-02T00:00:00+00:00', '--job-id', '4', '--raw', '--subdir', 'DAGS_FOLDER/w3c.py', '--cfg-path', '/tmp/tmp2an4ctzr']
[2025-04-03T14:24:03.591+0000] {standard_task_runner.py:88} INFO - Job 4: Subtask generate_analytics_report
[2025-04-03T14:24:03.649+0000] {task_command.py:423} INFO - Running <TaskInstance: Web_Log_Processing.generate_analytics_report scheduled__2025-04-02T00:00:00+00:00 [running]> on host 2d696db5e2ea
[2025-04-03T14:24:03.921+0000] {taskinstance.py:2480} INFO - Exporting env vars: AIRFLOW_CTX_DAG_OWNER='***' AIRFLOW_CTX_DAG_ID='Web_Log_Processing' AIRFLOW_CTX_TASK_ID='generate_analytics_report' AIRFLOW_CTX_EXECUTION_DATE='2025-04-02T00:00:00+00:00' AIRFLOW_CTX_TRY_NUMBER='1' AIRFLOW_CTX_DAG_RUN_ID='scheduled__2025-04-02T00:00:00+00:00'
[2025-04-03T14:24:03.923+0000] {subprocess.py:63} INFO - Tmp dir root location: /tmp
[2025-04-03T14:24:03.925+0000] {subprocess.py:75} INFO - Running command: ['/usr/bin/bash', '-c', 'python /opt/***/dags/analytics.py']
[2025-04-03T14:24:03.935+0000] {subprocess.py:86} INFO - Output:
[2025-04-03T14:24:03.963+0000] {subprocess.py:93} INFO - python: can't open file '/opt/***/dags/analytics.py': [Errno 2] No such file or directory
[2025-04-03T14:24:03.966+0000] {subprocess.py:97} INFO - Command exited with return code 2
[2025-04-03T14:24:03.976+0000] {taskinstance.py:2698} ERROR - Task failed with exception
Traceback (most recent call last):
  File "/home/airflow/.local/lib/python3.8/site-packages/airflow/models/taskinstance.py", line 433, in _execute_task
    result = execute_callable(context=context, **execute_callable_kwargs)
  File "/home/airflow/.local/lib/python3.8/site-packages/airflow/operators/bash.py", line 212, in execute
    raise AirflowException(
airflow.exceptions.AirflowException: Bash command failed. The command returned a non-zero exit code 2.
[2025-04-03T14:24:03.980+0000] {taskinstance.py:1138} INFO - Marking task as UP_FOR_RETRY. dag_id=Web_Log_Processing, task_id=generate_analytics_report, execution_date=20250402T000000, start_date=20250403T142403, end_date=20250403T142403
[2025-04-03T14:24:03.994+0000] {standard_task_runner.py:107} ERROR - Failed to execute job 4 for task generate_analytics_report (Bash command failed. The command returned a non-zero exit code 2.; 342)
[2025-04-03T14:24:04.043+0000] {local_task_job_runner.py:234} INFO - Task exited with return code 1
[2025-04-03T14:24:04.077+0000] {taskinstance.py:3280} INFO - 0 downstream tasks scheduled from follow-on schedule check
[2025-04-03T14:30:31.818+0000] {taskinstance.py:1956} INFO - Dependencies all met for dep_context=non-requeueable deps ti=<TaskInstance: Web_Log_Processing.generate_analytics_report scheduled__2025-04-02T00:00:00+00:00 [queued]>
[2025-04-03T14:30:31.829+0000] {taskinstance.py:1956} INFO - Dependencies all met for dep_context=requeueable deps ti=<TaskInstance: Web_Log_Processing.generate_analytics_report scheduled__2025-04-02T00:00:00+00:00 [queued]>
[2025-04-03T14:30:31.829+0000] {taskinstance.py:2170} INFO - Starting attempt 1 of 4
[2025-04-03T14:30:31.849+0000] {taskinstance.py:2191} INFO - Executing <Task(BashOperator): generate_analytics_report> on 2025-04-02 00:00:00+00:00
[2025-04-03T14:30:31.855+0000] {standard_task_runner.py:60} INFO - Started process 228 to run task
[2025-04-03T14:30:31.858+0000] {standard_task_runner.py:87} INFO - Running: ['***', 'tasks', 'run', 'Web_Log_Processing', 'generate_analytics_report', 'scheduled__2025-04-02T00:00:00+00:00', '--job-id', '3', '--raw', '--subdir', 'DAGS_FOLDER/w3c.py', '--cfg-path', '/tmp/tmp41u23502']
[2025-04-03T14:30:31.861+0000] {standard_task_runner.py:88} INFO - Job 3: Subtask generate_analytics_report
[2025-04-03T14:30:31.922+0000] {task_command.py:423} INFO - Running <TaskInstance: Web_Log_Processing.generate_analytics_report scheduled__2025-04-02T00:00:00+00:00 [running]> on host af883e189a6c
[2025-04-03T14:30:32.213+0000] {taskinstance.py:2480} INFO - Exporting env vars: AIRFLOW_CTX_DAG_OWNER='***' AIRFLOW_CTX_DAG_ID='Web_Log_Processing' AIRFLOW_CTX_TASK_ID='generate_analytics_report' AIRFLOW_CTX_EXECUTION_DATE='2025-04-02T00:00:00+00:00' AIRFLOW_CTX_TRY_NUMBER='1' AIRFLOW_CTX_DAG_RUN_ID='scheduled__2025-04-02T00:00:00+00:00'
[2025-04-03T14:30:32.215+0000] {subprocess.py:63} INFO - Tmp dir root location: /tmp
[2025-04-03T14:30:32.216+0000] {subprocess.py:75} INFO - Running command: ['/usr/bin/bash', '-c', 'python /opt/***/dags/analytics.py']
[2025-04-03T14:30:32.226+0000] {subprocess.py:86} INFO - Output:
[2025-04-03T14:30:32.257+0000] {subprocess.py:93} INFO - python: can't open file '/opt/***/dags/analytics.py': [Errno 2] No such file or directory
[2025-04-03T14:30:32.260+0000] {subprocess.py:97} INFO - Command exited with return code 2
[2025-04-03T14:30:32.272+0000] {taskinstance.py:2698} ERROR - Task failed with exception
Traceback (most recent call last):
  File "/home/airflow/.local/lib/python3.8/site-packages/airflow/models/taskinstance.py", line 433, in _execute_task
    result = execute_callable(context=context, **execute_callable_kwargs)
  File "/home/airflow/.local/lib/python3.8/site-packages/airflow/operators/bash.py", line 212, in execute
    raise AirflowException(
airflow.exceptions.AirflowException: Bash command failed. The command returned a non-zero exit code 2.
[2025-04-03T14:30:32.276+0000] {taskinstance.py:1138} INFO - Marking task as UP_FOR_RETRY. dag_id=Web_Log_Processing, task_id=generate_analytics_report, execution_date=20250402T000000, start_date=20250403T143031, end_date=20250403T143032
[2025-04-03T14:30:32.305+0000] {standard_task_runner.py:107} ERROR - Failed to execute job 3 for task generate_analytics_report (Bash command failed. The command returned a non-zero exit code 2.; 228)
[2025-04-03T14:30:32.354+0000] {local_task_job_runner.py:234} INFO - Task exited with return code 1
[2025-04-03T14:30:32.383+0000] {taskinstance.py:3280} INFO - 0 downstream tasks scheduled from follow-on schedule check
[2025-04-03T14:54:22.969+0000] {taskinstance.py:1956} INFO - Dependencies all met for dep_context=non-requeueable deps ti=<TaskInstance: Web_Log_Processing.generate_analytics_report scheduled__2025-04-02T00:00:00+00:00 [queued]>
[2025-04-03T14:54:22.981+0000] {taskinstance.py:1956} INFO - Dependencies all met for dep_context=requeueable deps ti=<TaskInstance: Web_Log_Processing.generate_analytics_report scheduled__2025-04-02T00:00:00+00:00 [queued]>
[2025-04-03T14:54:23.014+0000] {taskinstance.py:2170} INFO - Starting attempt 1 of 4
[2025-04-03T14:54:23.062+0000] {taskinstance.py:2191} INFO - Executing <Task(BashOperator): generate_analytics_report> on 2025-04-02 00:00:00+00:00
[2025-04-03T14:54:23.110+0000] {standard_task_runner.py:60} INFO - Started process 239 to run task
[2025-04-03T14:54:23.114+0000] {standard_task_runner.py:87} INFO - Running: ['***', 'tasks', 'run', 'Web_Log_Processing', 'generate_analytics_report', 'scheduled__2025-04-02T00:00:00+00:00', '--job-id', '3', '--raw', '--subdir', 'DAGS_FOLDER/w3c.py', '--cfg-path', '/tmp/tmpyf_hozx3']
[2025-04-03T14:54:23.137+0000] {standard_task_runner.py:88} INFO - Job 3: Subtask generate_analytics_report
[2025-04-03T14:54:23.208+0000] {task_command.py:423} INFO - Running <TaskInstance: Web_Log_Processing.generate_analytics_report scheduled__2025-04-02T00:00:00+00:00 [running]> on host 5deddec5fc9b
[2025-04-03T14:54:23.442+0000] {taskinstance.py:2480} INFO - Exporting env vars: AIRFLOW_CTX_DAG_OWNER='***' AIRFLOW_CTX_DAG_ID='Web_Log_Processing' AIRFLOW_CTX_TASK_ID='generate_analytics_report' AIRFLOW_CTX_EXECUTION_DATE='2025-04-02T00:00:00+00:00' AIRFLOW_CTX_TRY_NUMBER='1' AIRFLOW_CTX_DAG_RUN_ID='scheduled__2025-04-02T00:00:00+00:00'
[2025-04-03T14:54:23.444+0000] {subprocess.py:63} INFO - Tmp dir root location: /tmp
[2025-04-03T14:54:23.445+0000] {subprocess.py:75} INFO - Running command: ['/usr/bin/bash', '-c', 'python /opt/***/dags/analytics.py']
[2025-04-03T14:54:23.455+0000] {subprocess.py:86} INFO - Output:
[2025-04-03T14:54:23.487+0000] {subprocess.py:93} INFO - python: can't open file '/opt/***/dags/analytics.py': [Errno 2] No such file or directory
[2025-04-03T14:54:23.490+0000] {subprocess.py:97} INFO - Command exited with return code 2
[2025-04-03T14:54:23.502+0000] {taskinstance.py:2698} ERROR - Task failed with exception
Traceback (most recent call last):
  File "/home/airflow/.local/lib/python3.8/site-packages/airflow/models/taskinstance.py", line 433, in _execute_task
    result = execute_callable(context=context, **execute_callable_kwargs)
  File "/home/airflow/.local/lib/python3.8/site-packages/airflow/operators/bash.py", line 212, in execute
    raise AirflowException(
airflow.exceptions.AirflowException: Bash command failed. The command returned a non-zero exit code 2.
[2025-04-03T14:54:23.505+0000] {taskinstance.py:1138} INFO - Marking task as UP_FOR_RETRY. dag_id=Web_Log_Processing, task_id=generate_analytics_report, execution_date=20250402T000000, start_date=20250403T145422, end_date=20250403T145423
[2025-04-03T14:54:23.519+0000] {standard_task_runner.py:107} ERROR - Failed to execute job 3 for task generate_analytics_report (Bash command failed. The command returned a non-zero exit code 2.; 239)
[2025-04-03T14:54:23.548+0000] {local_task_job_runner.py:234} INFO - Task exited with return code 1
[2025-04-03T14:54:23.565+0000] {taskinstance.py:3280} INFO - 0 downstream tasks scheduled from follow-on schedule check
