[2025-04-03T15:45:36.229+0000] {taskinstance.py:1956} INFO - Dependencies all met for dep_context=non-requeueable deps ti=<TaskInstance: Web_Log_Processing.generate_star_schema scheduled__2025-04-02T00:00:00+00:00 [queued]>
[2025-04-03T15:45:36.241+0000] {taskinstance.py:1956} INFO - Dependencies all met for dep_context=requeueable deps ti=<TaskInstance: Web_Log_Processing.generate_star_schema scheduled__2025-04-02T00:00:00+00:00 [queued]>
[2025-04-03T15:45:36.242+0000] {taskinstance.py:2170} INFO - Starting attempt 1 of 4
[2025-04-03T15:45:36.255+0000] {taskinstance.py:2191} INFO - Executing <Task(PythonOperator): generate_star_schema> on 2025-04-02 00:00:00+00:00
[2025-04-03T15:45:36.260+0000] {standard_task_runner.py:60} INFO - Started process 228 to run task
[2025-04-03T15:45:36.264+0000] {standard_task_runner.py:87} INFO - Running: ['***', 'tasks', 'run', 'Web_Log_Processing', 'generate_star_schema', 'scheduled__2025-04-02T00:00:00+00:00', '--job-id', '3', '--raw', '--subdir', 'DAGS_FOLDER/w3c.py', '--cfg-path', '/tmp/tmpf2nyv0qy']
[2025-04-03T15:45:36.267+0000] {standard_task_runner.py:88} INFO - Job 3: Subtask generate_star_schema
[2025-04-03T15:45:36.324+0000] {task_command.py:423} INFO - Running <TaskInstance: Web_Log_Processing.generate_star_schema scheduled__2025-04-02T00:00:00+00:00 [running]> on host 345a2468dc45
[2025-04-03T15:45:36.586+0000] {taskinstance.py:2480} INFO - Exporting env vars: AIRFLOW_CTX_DAG_OWNER='***' AIRFLOW_CTX_DAG_ID='Web_Log_Processing' AIRFLOW_CTX_TASK_ID='generate_star_schema' AIRFLOW_CTX_EXECUTION_DATE='2025-04-02T00:00:00+00:00' AIRFLOW_CTX_TRY_NUMBER='1' AIRFLOW_CTX_DAG_RUN_ID='scheduled__2025-04-02T00:00:00+00:00'
[2025-04-03T15:45:36.599+0000] {logging_mixin.py:188} INFO - Reading combined CSV from: /opt/***/data/StagingArea/CombinedLogs.csv
[2025-04-03T15:45:37.086+0000] {logging_mixin.py:188} INFO - Loaded 89814 rows from the combined CSV.
[2025-04-03T15:45:37.091+0000] {logging_mixin.py:188} INFO - Adding derived columns...
[2025-04-03T15:45:37.219+0000] {taskinstance.py:2698} ERROR - Task failed with exception
Traceback (most recent call last):
  File "/opt/airflow/dags/w3c.py", line 107, in process_logs
    df["ErrorType"] = df["sc-status"].apply(lambda x: "ClientError" if x.startswith("4") else "ServerError" if x.startswith("5") else None)
  File "/home/airflow/.local/lib/python3.8/site-packages/pandas/core/series.py", line 4630, in apply
    return SeriesApply(self, func, convert_dtype, args, kwargs).apply()
  File "/home/airflow/.local/lib/python3.8/site-packages/pandas/core/apply.py", line 1025, in apply
    return self.apply_standard()
  File "/home/airflow/.local/lib/python3.8/site-packages/pandas/core/apply.py", line 1076, in apply_standard
    mapped = lib.map_infer(
  File "pandas/_libs/lib.pyx", line 2834, in pandas._libs.lib.map_infer
  File "/opt/airflow/dags/w3c.py", line 107, in <lambda>
    df["ErrorType"] = df["sc-status"].apply(lambda x: "ClientError" if x.startswith("4") else "ServerError" if x.startswith("5") else None)
AttributeError: 'int' object has no attribute 'startswith'

During handling of the above exception, another exception occurred:

Traceback (most recent call last):
  File "/home/airflow/.local/lib/python3.8/site-packages/airflow/models/taskinstance.py", line 433, in _execute_task
    result = execute_callable(context=context, **execute_callable_kwargs)
  File "/home/airflow/.local/lib/python3.8/site-packages/airflow/operators/python.py", line 199, in execute
    return_value = self.execute_callable()
  File "/home/airflow/.local/lib/python3.8/site-packages/airflow/operators/python.py", line 216, in execute_callable
    return self.python_callable(*self.op_args, **self.op_kwargs)
  File "/opt/airflow/dags/w3c.py", line 131, in process_logs
    raise AirflowException(f"Log processing failed: {str(e)}")
airflow.exceptions.AirflowException: Log processing failed: 'int' object has no attribute 'startswith'
[2025-04-03T15:45:37.233+0000] {taskinstance.py:1138} INFO - Marking task as UP_FOR_RETRY. dag_id=Web_Log_Processing, task_id=generate_star_schema, execution_date=20250402T000000, start_date=20250403T154536, end_date=20250403T154537
[2025-04-03T15:45:37.248+0000] {standard_task_runner.py:107} ERROR - Failed to execute job 3 for task generate_star_schema (Log processing failed: 'int' object has no attribute 'startswith'; 228)
[2025-04-03T15:45:37.281+0000] {local_task_job_runner.py:234} INFO - Task exited with return code 1
[2025-04-03T15:45:37.296+0000] {taskinstance.py:3280} INFO - 0 downstream tasks scheduled from follow-on schedule check
[2025-04-03T16:38:13.491+0000] {taskinstance.py:1956} INFO - Dependencies all met for dep_context=non-requeueable deps ti=<TaskInstance: Web_Log_Processing.generate_star_schema scheduled__2025-04-02T00:00:00+00:00 [queued]>
[2025-04-03T16:38:13.504+0000] {taskinstance.py:1956} INFO - Dependencies all met for dep_context=requeueable deps ti=<TaskInstance: Web_Log_Processing.generate_star_schema scheduled__2025-04-02T00:00:00+00:00 [queued]>
[2025-04-03T16:38:13.505+0000] {taskinstance.py:2170} INFO - Starting attempt 1 of 4
[2025-04-03T16:38:13.527+0000] {taskinstance.py:2191} INFO - Executing <Task(PythonOperator): generate_star_schema> on 2025-04-02 00:00:00+00:00
[2025-04-03T16:38:13.533+0000] {standard_task_runner.py:60} INFO - Started process 239 to run task
[2025-04-03T16:38:13.538+0000] {standard_task_runner.py:87} INFO - Running: ['***', 'tasks', 'run', 'Web_Log_Processing', 'generate_star_schema', 'scheduled__2025-04-02T00:00:00+00:00', '--job-id', '3', '--raw', '--subdir', 'DAGS_FOLDER/w3c.py', '--cfg-path', '/tmp/tmpr2ke48_x']
[2025-04-03T16:38:13.541+0000] {standard_task_runner.py:88} INFO - Job 3: Subtask generate_star_schema
[2025-04-03T16:38:13.611+0000] {task_command.py:423} INFO - Running <TaskInstance: Web_Log_Processing.generate_star_schema scheduled__2025-04-02T00:00:00+00:00 [running]> on host 9b170102d235
[2025-04-03T16:38:13.909+0000] {taskinstance.py:2480} INFO - Exporting env vars: AIRFLOW_CTX_DAG_OWNER='***' AIRFLOW_CTX_DAG_ID='Web_Log_Processing' AIRFLOW_CTX_TASK_ID='generate_star_schema' AIRFLOW_CTX_EXECUTION_DATE='2025-04-02T00:00:00+00:00' AIRFLOW_CTX_TRY_NUMBER='1' AIRFLOW_CTX_DAG_RUN_ID='scheduled__2025-04-02T00:00:00+00:00'
[2025-04-03T16:38:13.922+0000] {logging_mixin.py:188} INFO - Reading combined CSV from: /opt/***/data/StagingArea/CombinedLogs.csv
[2025-04-03T16:38:14.735+0000] {logging_mixin.py:188} WARNING - /opt/***/dags/w3c.py:92 DtypeWarning: Columns (10,11) have mixed types. Specify dtype option on import or set low_memory=False.
[2025-04-03T16:38:14.838+0000] {logging_mixin.py:188} INFO - Loaded 154463 rows from the combined CSV.
[2025-04-03T16:38:14.838+0000] {logging_mixin.py:188} INFO - Adding derived columns...
[2025-04-03T16:38:15.091+0000] {taskinstance.py:2698} ERROR - Task failed with exception
Traceback (most recent call last):
  File "/opt/airflow/dags/w3c.py", line 107, in process_logs
    df["ErrorType"] = df["sc-status"].apply(lambda x: "ClientError" if x.startswith("4") else "ServerError" if x.startswith("5") else None)
  File "/home/airflow/.local/lib/python3.8/site-packages/pandas/core/series.py", line 4630, in apply
    return SeriesApply(self, func, convert_dtype, args, kwargs).apply()
  File "/home/airflow/.local/lib/python3.8/site-packages/pandas/core/apply.py", line 1025, in apply
    return self.apply_standard()
  File "/home/airflow/.local/lib/python3.8/site-packages/pandas/core/apply.py", line 1076, in apply_standard
    mapped = lib.map_infer(
  File "pandas/_libs/lib.pyx", line 2834, in pandas._libs.lib.map_infer
  File "/opt/airflow/dags/w3c.py", line 107, in <lambda>
    df["ErrorType"] = df["sc-status"].apply(lambda x: "ClientError" if x.startswith("4") else "ServerError" if x.startswith("5") else None)
AttributeError: 'int' object has no attribute 'startswith'

During handling of the above exception, another exception occurred:

Traceback (most recent call last):
  File "/home/airflow/.local/lib/python3.8/site-packages/airflow/models/taskinstance.py", line 433, in _execute_task
    result = execute_callable(context=context, **execute_callable_kwargs)
  File "/home/airflow/.local/lib/python3.8/site-packages/airflow/operators/python.py", line 199, in execute
    return_value = self.execute_callable()
  File "/home/airflow/.local/lib/python3.8/site-packages/airflow/operators/python.py", line 216, in execute_callable
    return self.python_callable(*self.op_args, **self.op_kwargs)
  File "/opt/airflow/dags/w3c.py", line 161, in process_logs
    raise AirflowException(f"Log processing failed: {str(e)}")
airflow.exceptions.AirflowException: Log processing failed: 'int' object has no attribute 'startswith'
[2025-04-03T16:38:15.304+0000] {taskinstance.py:1138} INFO - Marking task as UP_FOR_RETRY. dag_id=Web_Log_Processing, task_id=generate_star_schema, execution_date=20250402T000000, start_date=20250403T163813, end_date=20250403T163815
[2025-04-03T16:38:15.448+0000] {standard_task_runner.py:107} ERROR - Failed to execute job 3 for task generate_star_schema (Log processing failed: 'int' object has no attribute 'startswith'; 239)
[2025-04-03T16:38:15.520+0000] {local_task_job_runner.py:234} INFO - Task exited with return code 1
[2025-04-03T16:38:15.556+0000] {taskinstance.py:3280} INFO - 0 downstream tasks scheduled from follow-on schedule check
