[2025-04-03T15:50:38.565+0000] {taskinstance.py:1956} INFO - Dependencies all met for dep_context=non-requeueable deps ti=<TaskInstance: Web_Log_Processing.generate_star_schema scheduled__2025-04-02T00:00:00+00:00 [queued]>
[2025-04-03T15:50:38.576+0000] {taskinstance.py:1956} INFO - Dependencies all met for dep_context=requeueable deps ti=<TaskInstance: Web_Log_Processing.generate_star_schema scheduled__2025-04-02T00:00:00+00:00 [queued]>
[2025-04-03T15:50:38.577+0000] {taskinstance.py:2170} INFO - Starting attempt 2 of 4
[2025-04-03T15:50:38.595+0000] {taskinstance.py:2191} INFO - Executing <Task(PythonOperator): generate_star_schema> on 2025-04-02 00:00:00+00:00
[2025-04-03T15:50:38.602+0000] {standard_task_runner.py:60} INFO - Started process 341 to run task
[2025-04-03T15:50:38.606+0000] {standard_task_runner.py:87} INFO - Running: ['***', 'tasks', 'run', 'Web_Log_Processing', 'generate_star_schema', 'scheduled__2025-04-02T00:00:00+00:00', '--job-id', '4', '--raw', '--subdir', 'DAGS_FOLDER/w3c.py', '--cfg-path', '/tmp/tmpxkbpszzm']
[2025-04-03T15:50:38.611+0000] {standard_task_runner.py:88} INFO - Job 4: Subtask generate_star_schema
[2025-04-03T15:50:38.670+0000] {task_command.py:423} INFO - Running <TaskInstance: Web_Log_Processing.generate_star_schema scheduled__2025-04-02T00:00:00+00:00 [running]> on host 345a2468dc45
[2025-04-03T15:50:38.919+0000] {taskinstance.py:2480} INFO - Exporting env vars: AIRFLOW_CTX_DAG_OWNER='***' AIRFLOW_CTX_DAG_ID='Web_Log_Processing' AIRFLOW_CTX_TASK_ID='generate_star_schema' AIRFLOW_CTX_EXECUTION_DATE='2025-04-02T00:00:00+00:00' AIRFLOW_CTX_TRY_NUMBER='2' AIRFLOW_CTX_DAG_RUN_ID='scheduled__2025-04-02T00:00:00+00:00'
[2025-04-03T15:50:38.931+0000] {logging_mixin.py:188} INFO - Reading combined CSV from: /opt/***/data/StagingArea/CombinedLogs.csv
[2025-04-03T15:50:39.890+0000] {logging_mixin.py:188} INFO - Loaded 89814 rows from the combined CSV.
[2025-04-03T15:50:39.891+0000] {logging_mixin.py:188} INFO - Adding derived columns...
[2025-04-03T15:50:39.987+0000] {taskinstance.py:2698} ERROR - Task failed with exception
Traceback (most recent call last):
  File "/opt/airflow/dags/w3c.py", line 107, in process_logs
    df["ErrorType"] = df["sc-status"].apply(lambda x: "ClientError" if x.startswith("4") else "ServerError" if x.startswith("5") else None)
  File "/home/airflow/.local/lib/python3.8/site-packages/pandas/core/series.py", line 4630, in apply
    return SeriesApply(self, func, convert_dtype, args, kwargs).apply()
  File "/home/airflow/.local/lib/python3.8/site-packages/pandas/core/apply.py", line 1025, in apply
    return self.apply_standard()
  File "/home/airflow/.local/lib/python3.8/site-packages/pandas/core/apply.py", line 1076, in apply_standard
    mapped = lib.map_infer(
  File "pandas/_libs/lib.pyx", line 2834, in pandas._libs.lib.map_infer
  File "/opt/airflow/dags/w3c.py", line 107, in <lambda>
    df["ErrorType"] = df["sc-status"].apply(lambda x: "ClientError" if x.startswith("4") else "ServerError" if x.startswith("5") else None)
AttributeError: 'int' object has no attribute 'startswith'

During handling of the above exception, another exception occurred:

Traceback (most recent call last):
  File "/home/airflow/.local/lib/python3.8/site-packages/airflow/models/taskinstance.py", line 433, in _execute_task
    result = execute_callable(context=context, **execute_callable_kwargs)
  File "/home/airflow/.local/lib/python3.8/site-packages/airflow/operators/python.py", line 199, in execute
    return_value = self.execute_callable()
  File "/home/airflow/.local/lib/python3.8/site-packages/airflow/operators/python.py", line 216, in execute_callable
    return self.python_callable(*self.op_args, **self.op_kwargs)
  File "/opt/airflow/dags/w3c.py", line 131, in process_logs
    raise AirflowException(f"Log processing failed: {str(e)}")
airflow.exceptions.AirflowException: Log processing failed: 'int' object has no attribute 'startswith'
[2025-04-03T15:50:40.004+0000] {taskinstance.py:1138} INFO - Marking task as UP_FOR_RETRY. dag_id=Web_Log_Processing, task_id=generate_star_schema, execution_date=20250402T000000, start_date=20250403T155038, end_date=20250403T155040
[2025-04-03T15:50:40.018+0000] {standard_task_runner.py:107} ERROR - Failed to execute job 4 for task generate_star_schema (Log processing failed: 'int' object has no attribute 'startswith'; 341)
[2025-04-03T15:50:40.066+0000] {local_task_job_runner.py:234} INFO - Task exited with return code 1
[2025-04-03T15:50:40.084+0000] {taskinstance.py:3280} INFO - 0 downstream tasks scheduled from follow-on schedule check
