[2025-04-02T15:51:00.085+0000] {taskinstance.py:1956} INFO - Dependencies all met for dep_context=non-requeueable deps ti=<TaskInstance: Web_Log_Processing.generate_analytics_report scheduled__2025-04-01T00:00:00+00:00 [queued]>
[2025-04-02T15:51:00.098+0000] {taskinstance.py:1956} INFO - Dependencies all met for dep_context=requeueable deps ti=<TaskInstance: Web_Log_Processing.generate_analytics_report scheduled__2025-04-01T00:00:00+00:00 [queued]>
[2025-04-02T15:51:00.099+0000] {taskinstance.py:2170} INFO - Starting attempt 4 of 4
[2025-04-02T15:51:00.117+0000] {taskinstance.py:2191} INFO - Executing <Task(BashOperator): generate_analytics_report> on 2025-04-01 00:00:00+00:00
[2025-04-02T15:51:00.123+0000] {standard_task_runner.py:60} INFO - Started process 829 to run task
[2025-04-02T15:51:00.128+0000] {standard_task_runner.py:87} INFO - Running: ['***', 'tasks', 'run', 'Web_Log_Processing', 'generate_analytics_report', 'scheduled__2025-04-01T00:00:00+00:00', '--job-id', '9', '--raw', '--subdir', 'DAGS_FOLDER/w3c.py', '--cfg-path', '/tmp/tmpo6mttb31']
[2025-04-02T15:51:00.131+0000] {standard_task_runner.py:88} INFO - Job 9: Subtask generate_analytics_report
[2025-04-02T15:51:00.193+0000] {task_command.py:423} INFO - Running <TaskInstance: Web_Log_Processing.generate_analytics_report scheduled__2025-04-01T00:00:00+00:00 [running]> on host decb7b281929
[2025-04-02T15:51:00.279+0000] {taskinstance.py:2480} INFO - Exporting env vars: AIRFLOW_CTX_DAG_OWNER='***' AIRFLOW_CTX_DAG_ID='Web_Log_Processing' AIRFLOW_CTX_TASK_ID='generate_analytics_report' AIRFLOW_CTX_EXECUTION_DATE='2025-04-01T00:00:00+00:00' AIRFLOW_CTX_TRY_NUMBER='4' AIRFLOW_CTX_DAG_RUN_ID='scheduled__2025-04-01T00:00:00+00:00'
[2025-04-02T15:51:00.281+0000] {subprocess.py:63} INFO - Tmp dir root location: /tmp
[2025-04-02T15:51:00.284+0000] {subprocess.py:75} INFO - Running command: ['/usr/bin/bash', '-c', 'python /opt/***/dags/analytics.py']
[2025-04-02T15:51:00.293+0000] {subprocess.py:86} INFO - Output:
[2025-04-02T15:51:00.346+0000] {subprocess.py:93} INFO - python: can't open file '/opt/***/dags/analytics.py': [Errno 2] No such file or directory
[2025-04-02T15:51:00.350+0000] {subprocess.py:97} INFO - Command exited with return code 2
[2025-04-02T15:51:00.365+0000] {taskinstance.py:2698} ERROR - Task failed with exception
Traceback (most recent call last):
  File "/home/airflow/.local/lib/python3.8/site-packages/airflow/models/taskinstance.py", line 433, in _execute_task
    result = execute_callable(context=context, **execute_callable_kwargs)
  File "/home/airflow/.local/lib/python3.8/site-packages/airflow/operators/bash.py", line 212, in execute
    raise AirflowException(
airflow.exceptions.AirflowException: Bash command failed. The command returned a non-zero exit code 2.
[2025-04-02T15:51:00.370+0000] {taskinstance.py:1138} INFO - Marking task as FAILED. dag_id=Web_Log_Processing, task_id=generate_analytics_report, execution_date=20250401T000000, start_date=20250402T155100, end_date=20250402T155100
[2025-04-02T15:51:00.385+0000] {standard_task_runner.py:107} ERROR - Failed to execute job 9 for task generate_analytics_report (Bash command failed. The command returned a non-zero exit code 2.; 829)
[2025-04-02T15:51:00.421+0000] {local_task_job_runner.py:234} INFO - Task exited with return code 1
[2025-04-02T15:51:00.438+0000] {taskinstance.py:3280} INFO - 0 downstream tasks scheduled from follow-on schedule check
[2025-04-02T16:59:27.336+0000] {taskinstance.py:1956} INFO - Dependencies all met for dep_context=non-requeueable deps ti=<TaskInstance: Web_Log_Processing.generate_analytics_report scheduled__2025-04-01T00:00:00+00:00 [queued]>
[2025-04-02T16:59:27.348+0000] {taskinstance.py:1956} INFO - Dependencies all met for dep_context=requeueable deps ti=<TaskInstance: Web_Log_Processing.generate_analytics_report scheduled__2025-04-01T00:00:00+00:00 [queued]>
[2025-04-02T16:59:27.349+0000] {taskinstance.py:2170} INFO - Starting attempt 4 of 4
[2025-04-02T16:59:27.364+0000] {taskinstance.py:2191} INFO - Executing <Task(BashOperator): generate_analytics_report> on 2025-04-01 00:00:00+00:00
[2025-04-02T16:59:27.371+0000] {standard_task_runner.py:60} INFO - Started process 795 to run task
[2025-04-02T16:59:27.376+0000] {standard_task_runner.py:87} INFO - Running: ['***', 'tasks', 'run', 'Web_Log_Processing', 'generate_analytics_report', 'scheduled__2025-04-01T00:00:00+00:00', '--job-id', '18', '--raw', '--subdir', 'DAGS_FOLDER/w3c.py', '--cfg-path', '/tmp/tmpszuf6dit']
[2025-04-02T16:59:27.380+0000] {standard_task_runner.py:88} INFO - Job 18: Subtask generate_analytics_report
[2025-04-02T16:59:27.442+0000] {task_command.py:423} INFO - Running <TaskInstance: Web_Log_Processing.generate_analytics_report scheduled__2025-04-01T00:00:00+00:00 [running]> on host e3653afa66c4
[2025-04-02T16:59:27.709+0000] {taskinstance.py:2480} INFO - Exporting env vars: AIRFLOW_CTX_DAG_OWNER='***' AIRFLOW_CTX_DAG_ID='Web_Log_Processing' AIRFLOW_CTX_TASK_ID='generate_analytics_report' AIRFLOW_CTX_EXECUTION_DATE='2025-04-01T00:00:00+00:00' AIRFLOW_CTX_TRY_NUMBER='4' AIRFLOW_CTX_DAG_RUN_ID='scheduled__2025-04-01T00:00:00+00:00'
[2025-04-02T16:59:27.710+0000] {subprocess.py:63} INFO - Tmp dir root location: /tmp
[2025-04-02T16:59:27.713+0000] {subprocess.py:75} INFO - Running command: ['/usr/bin/bash', '-c', 'python /opt/***/dags/analytics.py']
[2025-04-02T16:59:27.728+0000] {subprocess.py:86} INFO - Output:
[2025-04-02T16:59:27.782+0000] {subprocess.py:93} INFO - python: can't open file '/opt/***/dags/analytics.py': [Errno 2] No such file or directory
[2025-04-02T16:59:27.786+0000] {subprocess.py:97} INFO - Command exited with return code 2
[2025-04-02T16:59:27.797+0000] {taskinstance.py:2698} ERROR - Task failed with exception
Traceback (most recent call last):
  File "/home/airflow/.local/lib/python3.8/site-packages/airflow/models/taskinstance.py", line 433, in _execute_task
    result = execute_callable(context=context, **execute_callable_kwargs)
  File "/home/airflow/.local/lib/python3.8/site-packages/airflow/operators/bash.py", line 212, in execute
    raise AirflowException(
airflow.exceptions.AirflowException: Bash command failed. The command returned a non-zero exit code 2.
[2025-04-02T16:59:27.802+0000] {taskinstance.py:1138} INFO - Marking task as FAILED. dag_id=Web_Log_Processing, task_id=generate_analytics_report, execution_date=20250401T000000, start_date=20250402T165927, end_date=20250402T165927
[2025-04-02T16:59:27.819+0000] {standard_task_runner.py:107} ERROR - Failed to execute job 18 for task generate_analytics_report (Bash command failed. The command returned a non-zero exit code 2.; 795)
[2025-04-02T16:59:27.830+0000] {local_task_job_runner.py:234} INFO - Task exited with return code 1
[2025-04-02T16:59:27.850+0000] {taskinstance.py:3280} INFO - 0 downstream tasks scheduled from follow-on schedule check
