[2025-04-03T09:48:32.509+0000] {taskinstance.py:1956} INFO - Dependencies all met for dep_context=non-requeueable deps ti=<TaskInstance: Web_Log_Processing.process_log_files manual__2025-04-03T09:48:05.398700+00:00 [queued]>
[2025-04-03T09:48:32.518+0000] {taskinstance.py:1956} INFO - Dependencies all met for dep_context=requeueable deps ti=<TaskInstance: Web_Log_Processing.process_log_files manual__2025-04-03T09:48:05.398700+00:00 [queued]>
[2025-04-03T09:48:32.518+0000] {taskinstance.py:2170} INFO - Starting attempt 1 of 4
[2025-04-03T09:48:32.573+0000] {taskinstance.py:2191} INFO - Executing <Task(PythonOperator): process_log_files> on 2025-04-03 09:48:05.398700+00:00
[2025-04-03T09:48:32.579+0000] {standard_task_runner.py:60} INFO - Started process 421 to run task
[2025-04-03T09:48:32.582+0000] {standard_task_runner.py:87} INFO - Running: ['***', 'tasks', 'run', 'Web_Log_Processing', 'process_log_files', 'manual__2025-04-03T09:48:05.398700+00:00', '--job-id', '5', '--raw', '--subdir', 'DAGS_FOLDER/w3c.py', '--cfg-path', '/tmp/tmpnohi61xq']
[2025-04-03T09:48:32.585+0000] {standard_task_runner.py:88} INFO - Job 5: Subtask process_log_files
[2025-04-03T09:48:32.639+0000] {task_command.py:423} INFO - Running <TaskInstance: Web_Log_Processing.process_log_files manual__2025-04-03T09:48:05.398700+00:00 [running]> on host 72a8ea729061
[2025-04-03T09:48:32.923+0000] {taskinstance.py:2480} INFO - Exporting env vars: AIRFLOW_CTX_DAG_OWNER='***' AIRFLOW_CTX_DAG_ID='Web_Log_Processing' AIRFLOW_CTX_TASK_ID='process_log_files' AIRFLOW_CTX_EXECUTION_DATE='2025-04-03T09:48:05.398700+00:00' AIRFLOW_CTX_TRY_NUMBER='1' AIRFLOW_CTX_DAG_RUN_ID='manual__2025-04-03T09:48:05.398700+00:00'
[2025-04-03T09:48:32.935+0000] {taskinstance.py:2698} ERROR - Task failed with exception
Traceback (most recent call last):
  File "/opt/airflow/dags/w3c.py", line 111, in process_logs
    raise AirflowException("No valid log entries found in the log files.")
airflow.exceptions.AirflowException: No valid log entries found in the log files.

During handling of the above exception, another exception occurred:

Traceback (most recent call last):
  File "/home/airflow/.local/lib/python3.8/site-packages/airflow/models/taskinstance.py", line 433, in _execute_task
    result = execute_callable(context=context, **execute_callable_kwargs)
  File "/home/airflow/.local/lib/python3.8/site-packages/airflow/operators/python.py", line 199, in execute
    return_value = self.execute_callable()
  File "/home/airflow/.local/lib/python3.8/site-packages/airflow/operators/python.py", line 216, in execute_callable
    return self.python_callable(*self.op_args, **self.op_kwargs)
  File "/opt/airflow/dags/w3c.py", line 151, in process_logs
    raise AirflowException(f"Log processing failed: {str(e)}")
airflow.exceptions.AirflowException: Log processing failed: No valid log entries found in the log files.
[2025-04-03T09:48:32.947+0000] {taskinstance.py:1138} INFO - Marking task as UP_FOR_RETRY. dag_id=Web_Log_Processing, task_id=process_log_files, execution_date=20250403T094805, start_date=20250403T094832, end_date=20250403T094832
[2025-04-03T09:48:32.961+0000] {standard_task_runner.py:107} ERROR - Failed to execute job 5 for task process_log_files (Log processing failed: No valid log entries found in the log files.; 421)
[2025-04-03T09:48:32.997+0000] {local_task_job_runner.py:234} INFO - Task exited with return code 1
[2025-04-03T09:48:33.024+0000] {taskinstance.py:3280} INFO - 0 downstream tasks scheduled from follow-on schedule check
