[2025-04-03T09:58:36.473+0000] {taskinstance.py:1956} INFO - Dependencies all met for dep_context=non-requeueable deps ti=<TaskInstance: Web_Log_Processing.process_log_files manual__2025-04-03T09:48:05.398700+00:00 [queued]>
[2025-04-03T09:58:36.486+0000] {taskinstance.py:1956} INFO - Dependencies all met for dep_context=requeueable deps ti=<TaskInstance: Web_Log_Processing.process_log_files manual__2025-04-03T09:48:05.398700+00:00 [queued]>
[2025-04-03T09:58:36.487+0000] {taskinstance.py:2170} INFO - Starting attempt 3 of 4
[2025-04-03T09:58:36.508+0000] {taskinstance.py:2191} INFO - Executing <Task(PythonOperator): process_log_files> on 2025-04-03 09:48:05.398700+00:00
[2025-04-03T09:58:36.515+0000] {standard_task_runner.py:60} INFO - Started process 653 to run task
[2025-04-03T09:58:36.520+0000] {standard_task_runner.py:87} INFO - Running: ['***', 'tasks', 'run', 'Web_Log_Processing', 'process_log_files', 'manual__2025-04-03T09:48:05.398700+00:00', '--job-id', '7', '--raw', '--subdir', 'DAGS_FOLDER/w3c.py', '--cfg-path', '/tmp/tmpi8oqm546']
[2025-04-03T09:58:36.523+0000] {standard_task_runner.py:88} INFO - Job 7: Subtask process_log_files
[2025-04-03T09:58:36.589+0000] {task_command.py:423} INFO - Running <TaskInstance: Web_Log_Processing.process_log_files manual__2025-04-03T09:48:05.398700+00:00 [running]> on host 72a8ea729061
[2025-04-03T09:58:36.883+0000] {taskinstance.py:2480} INFO - Exporting env vars: AIRFLOW_CTX_DAG_OWNER='***' AIRFLOW_CTX_DAG_ID='Web_Log_Processing' AIRFLOW_CTX_TASK_ID='process_log_files' AIRFLOW_CTX_EXECUTION_DATE='2025-04-03T09:48:05.398700+00:00' AIRFLOW_CTX_TRY_NUMBER='3' AIRFLOW_CTX_DAG_RUN_ID='manual__2025-04-03T09:48:05.398700+00:00'
[2025-04-03T09:58:36.885+0000] {logging_mixin.py:188} INFO - Looking for log files in: d:/Documents/UK/University/BI/Repo/***-etl/data
[2025-04-03T09:58:36.887+0000] {logging_mixin.py:188} INFO - Files found: []
[2025-04-03T09:58:36.896+0000] {taskinstance.py:2698} ERROR - Task failed with exception
Traceback (most recent call last):
  File "/opt/airflow/dags/w3c.py", line 117, in process_logs
    raise AirflowException("No valid log entries found in the log files.")
airflow.exceptions.AirflowException: No valid log entries found in the log files.

During handling of the above exception, another exception occurred:

Traceback (most recent call last):
  File "/home/airflow/.local/lib/python3.8/site-packages/airflow/models/taskinstance.py", line 433, in _execute_task
    result = execute_callable(context=context, **execute_callable_kwargs)
  File "/home/airflow/.local/lib/python3.8/site-packages/airflow/operators/python.py", line 199, in execute
    return_value = self.execute_callable()
  File "/home/airflow/.local/lib/python3.8/site-packages/airflow/operators/python.py", line 216, in execute_callable
    return self.python_callable(*self.op_args, **self.op_kwargs)
  File "/opt/airflow/dags/w3c.py", line 157, in process_logs
    raise AirflowException(f"Log processing failed: {str(e)}")
airflow.exceptions.AirflowException: Log processing failed: No valid log entries found in the log files.
[2025-04-03T09:58:36.907+0000] {taskinstance.py:1138} INFO - Marking task as UP_FOR_RETRY. dag_id=Web_Log_Processing, task_id=process_log_files, execution_date=20250403T094805, start_date=20250403T095836, end_date=20250403T095836
[2025-04-03T09:58:36.922+0000] {standard_task_runner.py:107} ERROR - Failed to execute job 7 for task process_log_files (Log processing failed: No valid log entries found in the log files.; 653)
[2025-04-03T09:58:36.934+0000] {local_task_job_runner.py:234} INFO - Task exited with return code 1
[2025-04-03T09:58:36.965+0000] {taskinstance.py:3280} INFO - 0 downstream tasks scheduled from follow-on schedule check
