[2025-04-03T16:49:04.620+0000] {taskinstance.py:1956} INFO - Dependencies all met for dep_context=non-requeueable deps ti=<TaskInstance: Web_Log_Processing.generate_star_schema manual__2025-04-03T16:43:41.275219+00:00 [queued]>
[2025-04-03T16:49:04.632+0000] {taskinstance.py:1956} INFO - Dependencies all met for dep_context=requeueable deps ti=<TaskInstance: Web_Log_Processing.generate_star_schema manual__2025-04-03T16:43:41.275219+00:00 [queued]>
[2025-04-03T16:49:04.634+0000] {taskinstance.py:2170} INFO - Starting attempt 1 of 4
[2025-04-03T16:49:04.653+0000] {taskinstance.py:2191} INFO - Executing <Task(PythonOperator): generate_star_schema> on 2025-04-03 16:43:41.275219+00:00
[2025-04-03T16:49:04.659+0000] {standard_task_runner.py:60} INFO - Started process 557 to run task
[2025-04-03T16:49:04.664+0000] {standard_task_runner.py:87} INFO - Running: ['***', 'tasks', 'run', 'Web_Log_Processing', 'generate_star_schema', 'manual__2025-04-03T16:43:41.275219+00:00', '--job-id', '7', '--raw', '--subdir', 'DAGS_FOLDER/w3c.py', '--cfg-path', '/tmp/tmpe3q487y5']
[2025-04-03T16:49:04.667+0000] {standard_task_runner.py:88} INFO - Job 7: Subtask generate_star_schema
[2025-04-03T16:49:04.736+0000] {task_command.py:423} INFO - Running <TaskInstance: Web_Log_Processing.generate_star_schema manual__2025-04-03T16:43:41.275219+00:00 [running]> on host 9b170102d235
[2025-04-03T16:49:05.006+0000] {taskinstance.py:2480} INFO - Exporting env vars: AIRFLOW_CTX_DAG_OWNER='***' AIRFLOW_CTX_DAG_ID='Web_Log_Processing' AIRFLOW_CTX_TASK_ID='generate_star_schema' AIRFLOW_CTX_EXECUTION_DATE='2025-04-03T16:43:41.275219+00:00' AIRFLOW_CTX_TRY_NUMBER='1' AIRFLOW_CTX_DAG_RUN_ID='manual__2025-04-03T16:43:41.275219+00:00'
[2025-04-03T16:49:05.030+0000] {logging_mixin.py:188} INFO - Reading combined CSV from: /opt/***/data/StagingArea/CombinedLogs.csv
[2025-04-03T16:49:06.194+0000] {logging_mixin.py:188} INFO - Loaded 154463 rows from the combined CSV.
[2025-04-03T16:49:06.195+0000] {logging_mixin.py:188} INFO - Adding derived columns...
[2025-04-03T16:49:06.577+0000] {logging_mixin.py:188} INFO - Creating dimensions...
[2025-04-03T16:49:06.617+0000] {taskinstance.py:2698} ERROR - Task failed with exception
Traceback (most recent call last):
  File "/opt/airflow/dags/w3c.py", line 119, in process_logs
    dim_client = df[["c-ip", "city", "country"]].drop_duplicates().reset_index(drop=True)
  File "/home/airflow/.local/lib/python3.8/site-packages/pandas/core/frame.py", line 3767, in __getitem__
    indexer = self.columns._get_indexer_strict(key, "columns")[1]
  File "/home/airflow/.local/lib/python3.8/site-packages/pandas/core/indexes/base.py", line 5877, in _get_indexer_strict
    self._raise_if_missing(keyarr, indexer, axis_name)
  File "/home/airflow/.local/lib/python3.8/site-packages/pandas/core/indexes/base.py", line 5941, in _raise_if_missing
    raise KeyError(f"{not_found} not in index")
KeyError: "['city', 'country'] not in index"

During handling of the above exception, another exception occurred:

Traceback (most recent call last):
  File "/home/airflow/.local/lib/python3.8/site-packages/airflow/models/taskinstance.py", line 433, in _execute_task
    result = execute_callable(context=context, **execute_callable_kwargs)
  File "/home/airflow/.local/lib/python3.8/site-packages/airflow/operators/python.py", line 199, in execute
    return_value = self.execute_callable()
  File "/home/airflow/.local/lib/python3.8/site-packages/airflow/operators/python.py", line 216, in execute_callable
    return self.python_callable(*self.op_args, **self.op_kwargs)
  File "/opt/airflow/dags/w3c.py", line 165, in process_logs
    raise AirflowException(f"Log processing failed: {str(e)}")
airflow.exceptions.AirflowException: Log processing failed: "['city', 'country'] not in index"
[2025-04-03T16:49:06.643+0000] {taskinstance.py:1138} INFO - Marking task as UP_FOR_RETRY. dag_id=Web_Log_Processing, task_id=generate_star_schema, execution_date=20250403T164341, start_date=20250403T164904, end_date=20250403T164906
[2025-04-03T16:49:06.663+0000] {standard_task_runner.py:107} ERROR - Failed to execute job 7 for task generate_star_schema (Log processing failed: "['city', 'country'] not in index"; 557)
[2025-04-03T16:49:06.688+0000] {local_task_job_runner.py:234} INFO - Task exited with return code 1
[2025-04-03T16:49:06.711+0000] {taskinstance.py:3280} INFO - 0 downstream tasks scheduled from follow-on schedule check
