[2025-04-02T19:50:12.377+0000] {taskinstance.py:1956} INFO - Dependencies all met for dep_context=non-requeueable deps ti=<TaskInstance: Web_Log_Processing.process_log_files scheduled__2025-04-01T00:00:00+00:00 [queued]>
[2025-04-02T19:50:12.388+0000] {taskinstance.py:1956} INFO - Dependencies all met for dep_context=requeueable deps ti=<TaskInstance: Web_Log_Processing.process_log_files scheduled__2025-04-01T00:00:00+00:00 [queued]>
[2025-04-02T19:50:12.389+0000] {taskinstance.py:2170} INFO - Starting attempt 3 of 4
[2025-04-02T19:50:12.407+0000] {taskinstance.py:2191} INFO - Executing <Task(PythonOperator): process_log_files> on 2025-04-01 00:00:00+00:00
[2025-04-02T19:50:12.413+0000] {standard_task_runner.py:60} INFO - Started process 418 to run task
[2025-04-02T19:50:12.417+0000] {standard_task_runner.py:87} INFO - Running: ['***', 'tasks', 'run', 'Web_Log_Processing', 'process_log_files', 'scheduled__2025-04-01T00:00:00+00:00', '--job-id', '4', '--raw', '--subdir', 'DAGS_FOLDER/w3c.py', '--cfg-path', '/tmp/tmpxmhiclbw']
[2025-04-02T19:50:12.420+0000] {standard_task_runner.py:88} INFO - Job 4: Subtask process_log_files
[2025-04-02T19:50:12.485+0000] {task_command.py:423} INFO - Running <TaskInstance: Web_Log_Processing.process_log_files scheduled__2025-04-01T00:00:00+00:00 [running]> on host c8bdc85c7d51
[2025-04-02T19:50:12.775+0000] {taskinstance.py:2480} INFO - Exporting env vars: AIRFLOW_CTX_DAG_OWNER='***' AIRFLOW_CTX_DAG_ID='Web_Log_Processing' AIRFLOW_CTX_TASK_ID='process_log_files' AIRFLOW_CTX_EXECUTION_DATE='2025-04-01T00:00:00+00:00' AIRFLOW_CTX_TRY_NUMBER='3' AIRFLOW_CTX_DAG_RUN_ID='scheduled__2025-04-01T00:00:00+00:00'
[2025-04-02T19:50:12.803+0000] {taskinstance.py:2698} ERROR - Task failed with exception
Traceback (most recent call last):
  File "/opt/airflow/dags/w3c.py", line 129, in process_logs
    fact_table = df[["FullDate", "c-ip", "cs-method", "cs-uri-stem", "sc-status",
  File "/home/airflow/.local/lib/python3.8/site-packages/pandas/core/frame.py", line 3767, in __getitem__
    indexer = self.columns._get_indexer_strict(key, "columns")[1]
  File "/home/airflow/.local/lib/python3.8/site-packages/pandas/core/indexes/base.py", line 5877, in _get_indexer_strict
    self._raise_if_missing(keyarr, indexer, axis_name)
  File "/home/airflow/.local/lib/python3.8/site-packages/pandas/core/indexes/base.py", line 5941, in _raise_if_missing
    raise KeyError(f"{not_found} not in index")
KeyError: "['sc-bytes'] not in index"

During handling of the above exception, another exception occurred:

Traceback (most recent call last):
  File "/home/airflow/.local/lib/python3.8/site-packages/airflow/models/taskinstance.py", line 433, in _execute_task
    result = execute_callable(context=context, **execute_callable_kwargs)
  File "/home/airflow/.local/lib/python3.8/site-packages/airflow/operators/python.py", line 199, in execute
    return_value = self.execute_callable()
  File "/home/airflow/.local/lib/python3.8/site-packages/airflow/operators/python.py", line 216, in execute_callable
    return self.python_callable(*self.op_args, **self.op_kwargs)
  File "/opt/airflow/dags/w3c.py", line 145, in process_logs
    raise AirflowException(f"Log processing failed: {str(e)}")
airflow.exceptions.AirflowException: Log processing failed: "['sc-bytes'] not in index"
[2025-04-02T19:50:12.819+0000] {taskinstance.py:1138} INFO - Marking task as UP_FOR_RETRY. dag_id=Web_Log_Processing, task_id=process_log_files, execution_date=20250401T000000, start_date=20250402T195012, end_date=20250402T195012
[2025-04-02T19:50:12.834+0000] {standard_task_runner.py:107} ERROR - Failed to execute job 4 for task process_log_files (Log processing failed: "['sc-bytes'] not in index"; 418)
[2025-04-02T19:50:12.872+0000] {local_task_job_runner.py:234} INFO - Task exited with return code 1
[2025-04-02T19:50:12.897+0000] {taskinstance.py:3280} INFO - 0 downstream tasks scheduled from follow-on schedule check
[2025-04-02T20:49:52.379+0000] {taskinstance.py:1956} INFO - Dependencies all met for dep_context=non-requeueable deps ti=<TaskInstance: Web_Log_Processing.process_log_files scheduled__2025-04-01T00:00:00+00:00 [queued]>
[2025-04-02T20:49:52.394+0000] {taskinstance.py:1956} INFO - Dependencies all met for dep_context=requeueable deps ti=<TaskInstance: Web_Log_Processing.process_log_files scheduled__2025-04-01T00:00:00+00:00 [queued]>
[2025-04-02T20:49:52.395+0000] {taskinstance.py:2170} INFO - Starting attempt 3 of 6
[2025-04-02T20:49:52.421+0000] {taskinstance.py:2191} INFO - Executing <Task(PythonOperator): process_log_files> on 2025-04-01 00:00:00+00:00
[2025-04-02T20:49:52.429+0000] {standard_task_runner.py:60} INFO - Started process 332 to run task
[2025-04-02T20:49:52.440+0000] {standard_task_runner.py:87} INFO - Running: ['***', 'tasks', 'run', 'Web_Log_Processing', 'process_log_files', 'scheduled__2025-04-01T00:00:00+00:00', '--job-id', '4', '--raw', '--subdir', 'DAGS_FOLDER/w3c.py', '--cfg-path', '/tmp/tmp8ozgwh2l']
[2025-04-02T20:49:52.446+0000] {standard_task_runner.py:88} INFO - Job 4: Subtask process_log_files
[2025-04-02T20:49:52.525+0000] {task_command.py:423} INFO - Running <TaskInstance: Web_Log_Processing.process_log_files scheduled__2025-04-01T00:00:00+00:00 [running]> on host 4031425a0ee2
[2025-04-02T20:49:52.783+0000] {taskinstance.py:2480} INFO - Exporting env vars: AIRFLOW_CTX_DAG_OWNER='***' AIRFLOW_CTX_DAG_ID='Web_Log_Processing' AIRFLOW_CTX_TASK_ID='process_log_files' AIRFLOW_CTX_EXECUTION_DATE='2025-04-01T00:00:00+00:00' AIRFLOW_CTX_TRY_NUMBER='3' AIRFLOW_CTX_DAG_RUN_ID='scheduled__2025-04-01T00:00:00+00:00'
[2025-04-02T20:49:52.793+0000] {taskinstance.py:2698} ERROR - Task failed with exception
Traceback (most recent call last):
  File "/opt/airflow/dags/w3c.py", line 111, in process_logs
    raise AirflowException("No valid log entries found in the log files.")
airflow.exceptions.AirflowException: No valid log entries found in the log files.

During handling of the above exception, another exception occurred:

Traceback (most recent call last):
  File "/home/airflow/.local/lib/python3.8/site-packages/airflow/models/taskinstance.py", line 433, in _execute_task
    result = execute_callable(context=context, **execute_callable_kwargs)
  File "/home/airflow/.local/lib/python3.8/site-packages/airflow/operators/python.py", line 199, in execute
    return_value = self.execute_callable()
  File "/home/airflow/.local/lib/python3.8/site-packages/airflow/operators/python.py", line 216, in execute_callable
    return self.python_callable(*self.op_args, **self.op_kwargs)
  File "/opt/airflow/dags/w3c.py", line 157, in process_logs
    raise AirflowException(f"Log processing failed: {str(e)}")
airflow.exceptions.AirflowException: Log processing failed: No valid log entries found in the log files.
[2025-04-02T20:49:52.805+0000] {taskinstance.py:1138} INFO - Marking task as UP_FOR_RETRY. dag_id=Web_Log_Processing, task_id=process_log_files, execution_date=20250401T000000, start_date=20250402T204952, end_date=20250402T204952
[2025-04-02T20:49:52.819+0000] {standard_task_runner.py:107} ERROR - Failed to execute job 4 for task process_log_files (Log processing failed: No valid log entries found in the log files.; 332)
[2025-04-02T20:49:52.862+0000] {local_task_job_runner.py:234} INFO - Task exited with return code 1
[2025-04-02T20:49:52.898+0000] {taskinstance.py:3280} INFO - 0 downstream tasks scheduled from follow-on schedule check
