[2025-04-02T19:45:11.295+0000] {taskinstance.py:1956} INFO - Dependencies all met for dep_context=non-requeueable deps ti=<TaskInstance: Web_Log_Processing.process_log_files scheduled__2025-04-01T00:00:00+00:00 [queued]>
[2025-04-02T19:45:11.307+0000] {taskinstance.py:1956} INFO - Dependencies all met for dep_context=requeueable deps ti=<TaskInstance: Web_Log_Processing.process_log_files scheduled__2025-04-01T00:00:00+00:00 [queued]>
[2025-04-02T19:45:11.308+0000] {taskinstance.py:2170} INFO - Starting attempt 2 of 4
[2025-04-02T19:45:11.326+0000] {taskinstance.py:2191} INFO - Executing <Task(PythonOperator): process_log_files> on 2025-04-01 00:00:00+00:00
[2025-04-02T19:45:11.332+0000] {standard_task_runner.py:60} INFO - Started process 305 to run task
[2025-04-02T19:45:11.337+0000] {standard_task_runner.py:87} INFO - Running: ['***', 'tasks', 'run', 'Web_Log_Processing', 'process_log_files', 'scheduled__2025-04-01T00:00:00+00:00', '--job-id', '3', '--raw', '--subdir', 'DAGS_FOLDER/w3c.py', '--cfg-path', '/tmp/tmp2lyzdqel']
[2025-04-02T19:45:11.343+0000] {standard_task_runner.py:88} INFO - Job 3: Subtask process_log_files
[2025-04-02T19:45:11.418+0000] {task_command.py:423} INFO - Running <TaskInstance: Web_Log_Processing.process_log_files scheduled__2025-04-01T00:00:00+00:00 [running]> on host c8bdc85c7d51
[2025-04-02T19:45:11.691+0000] {taskinstance.py:2480} INFO - Exporting env vars: AIRFLOW_CTX_DAG_OWNER='***' AIRFLOW_CTX_DAG_ID='Web_Log_Processing' AIRFLOW_CTX_TASK_ID='process_log_files' AIRFLOW_CTX_EXECUTION_DATE='2025-04-01T00:00:00+00:00' AIRFLOW_CTX_TRY_NUMBER='2' AIRFLOW_CTX_DAG_RUN_ID='scheduled__2025-04-01T00:00:00+00:00'
[2025-04-02T19:45:11.716+0000] {taskinstance.py:2698} ERROR - Task failed with exception
Traceback (most recent call last):
  File "/opt/airflow/dags/w3c.py", line 129, in process_logs
    fact_table = df[["FullDate", "c-ip", "cs-method", "cs-uri-stem", "sc-status",
  File "/home/airflow/.local/lib/python3.8/site-packages/pandas/core/frame.py", line 3767, in __getitem__
    indexer = self.columns._get_indexer_strict(key, "columns")[1]
  File "/home/airflow/.local/lib/python3.8/site-packages/pandas/core/indexes/base.py", line 5877, in _get_indexer_strict
    self._raise_if_missing(keyarr, indexer, axis_name)
  File "/home/airflow/.local/lib/python3.8/site-packages/pandas/core/indexes/base.py", line 5941, in _raise_if_missing
    raise KeyError(f"{not_found} not in index")
KeyError: "['sc-bytes'] not in index"

During handling of the above exception, another exception occurred:

Traceback (most recent call last):
  File "/home/airflow/.local/lib/python3.8/site-packages/airflow/models/taskinstance.py", line 433, in _execute_task
    result = execute_callable(context=context, **execute_callable_kwargs)
  File "/home/airflow/.local/lib/python3.8/site-packages/airflow/operators/python.py", line 199, in execute
    return_value = self.execute_callable()
  File "/home/airflow/.local/lib/python3.8/site-packages/airflow/operators/python.py", line 216, in execute_callable
    return self.python_callable(*self.op_args, **self.op_kwargs)
  File "/opt/airflow/dags/w3c.py", line 145, in process_logs
    raise AirflowException(f"Log processing failed: {str(e)}")
airflow.exceptions.AirflowException: Log processing failed: "['sc-bytes'] not in index"
[2025-04-02T19:45:11.732+0000] {taskinstance.py:1138} INFO - Marking task as UP_FOR_RETRY. dag_id=Web_Log_Processing, task_id=process_log_files, execution_date=20250401T000000, start_date=20250402T194511, end_date=20250402T194511
[2025-04-02T19:45:11.746+0000] {standard_task_runner.py:107} ERROR - Failed to execute job 3 for task process_log_files (Log processing failed: "['sc-bytes'] not in index"; 305)
[2025-04-02T19:45:11.791+0000] {local_task_job_runner.py:234} INFO - Task exited with return code 1
[2025-04-02T19:45:11.815+0000] {taskinstance.py:3280} INFO - 0 downstream tasks scheduled from follow-on schedule check
[2025-04-02T20:47:29.418+0000] {taskinstance.py:1956} INFO - Dependencies all met for dep_context=non-requeueable deps ti=<TaskInstance: Web_Log_Processing.process_log_files scheduled__2025-04-01T00:00:00+00:00 [queued]>
[2025-04-02T20:47:29.451+0000] {taskinstance.py:1956} INFO - Dependencies all met for dep_context=requeueable deps ti=<TaskInstance: Web_Log_Processing.process_log_files scheduled__2025-04-01T00:00:00+00:00 [queued]>
[2025-04-02T20:47:29.467+0000] {taskinstance.py:2170} INFO - Starting attempt 2 of 4
[2025-04-02T20:47:29.538+0000] {taskinstance.py:2191} INFO - Executing <Task(PythonOperator): process_log_files> on 2025-04-01 00:00:00+00:00
[2025-04-02T20:47:29.555+0000] {standard_task_runner.py:60} INFO - Started process 283 to run task
[2025-04-02T20:47:29.567+0000] {standard_task_runner.py:87} INFO - Running: ['***', 'tasks', 'run', 'Web_Log_Processing', 'process_log_files', 'scheduled__2025-04-01T00:00:00+00:00', '--job-id', '3', '--raw', '--subdir', 'DAGS_FOLDER/w3c.py', '--cfg-path', '/tmp/tmpo2zhdcj7']
[2025-04-02T20:47:29.587+0000] {standard_task_runner.py:88} INFO - Job 3: Subtask process_log_files
[2025-04-02T20:47:29.719+0000] {task_command.py:423} INFO - Running <TaskInstance: Web_Log_Processing.process_log_files scheduled__2025-04-01T00:00:00+00:00 [running]> on host 4031425a0ee2
[2025-04-02T20:47:30.062+0000] {taskinstance.py:2480} INFO - Exporting env vars: AIRFLOW_CTX_DAG_OWNER='***' AIRFLOW_CTX_DAG_ID='Web_Log_Processing' AIRFLOW_CTX_TASK_ID='process_log_files' AIRFLOW_CTX_EXECUTION_DATE='2025-04-01T00:00:00+00:00' AIRFLOW_CTX_TRY_NUMBER='2' AIRFLOW_CTX_DAG_RUN_ID='scheduled__2025-04-01T00:00:00+00:00'
[2025-04-02T20:47:30.079+0000] {taskinstance.py:2698} ERROR - Task failed with exception
Traceback (most recent call last):
  File "/opt/airflow/dags/w3c.py", line 111, in process_logs
    df = pd.DataFrame(combined_data, columns=columns[:len(combined_data[0])])
IndexError: list index out of range

During handling of the above exception, another exception occurred:

Traceback (most recent call last):
  File "/home/airflow/.local/lib/python3.8/site-packages/airflow/models/taskinstance.py", line 433, in _execute_task
    result = execute_callable(context=context, **execute_callable_kwargs)
  File "/home/airflow/.local/lib/python3.8/site-packages/airflow/operators/python.py", line 199, in execute
    return_value = self.execute_callable()
  File "/home/airflow/.local/lib/python3.8/site-packages/airflow/operators/python.py", line 216, in execute_callable
    return self.python_callable(*self.op_args, **self.op_kwargs)
  File "/opt/airflow/dags/w3c.py", line 151, in process_logs
    raise AirflowException(f"Log processing failed: {str(e)}")
airflow.exceptions.AirflowException: Log processing failed: list index out of range
[2025-04-02T20:47:30.155+0000] {taskinstance.py:1138} INFO - Marking task as UP_FOR_RETRY. dag_id=Web_Log_Processing, task_id=process_log_files, execution_date=20250401T000000, start_date=20250402T204729, end_date=20250402T204730
[2025-04-02T20:47:30.178+0000] {standard_task_runner.py:107} ERROR - Failed to execute job 3 for task process_log_files (Log processing failed: list index out of range; 283)
[2025-04-02T20:47:30.193+0000] {local_task_job_runner.py:234} INFO - Task exited with return code 1
[2025-04-02T20:47:30.224+0000] {taskinstance.py:3280} INFO - 0 downstream tasks scheduled from follow-on schedule check
