[2025-04-02T21:00:11.221+0000] {taskinstance.py:1956} INFO - Dependencies all met for dep_context=non-requeueable deps ti=<TaskInstance: Web_Log_Processing.process_log_files scheduled__2025-04-01T00:00:00+00:00 [queued]>
[2025-04-02T21:00:11.232+0000] {taskinstance.py:1956} INFO - Dependencies all met for dep_context=requeueable deps ti=<TaskInstance: Web_Log_Processing.process_log_files scheduled__2025-04-01T00:00:00+00:00 [queued]>
[2025-04-02T21:00:11.233+0000] {taskinstance.py:2170} INFO - Starting attempt 6 of 8
[2025-04-02T21:00:11.250+0000] {taskinstance.py:2191} INFO - Executing <Task(PythonOperator): process_log_files> on 2025-04-01 00:00:00+00:00
[2025-04-02T21:00:11.256+0000] {standard_task_runner.py:60} INFO - Started process 561 to run task
[2025-04-02T21:00:11.260+0000] {standard_task_runner.py:87} INFO - Running: ['***', 'tasks', 'run', 'Web_Log_Processing', 'process_log_files', 'scheduled__2025-04-01T00:00:00+00:00', '--job-id', '7', '--raw', '--subdir', 'DAGS_FOLDER/w3c.py', '--cfg-path', '/tmp/tmp2pl9wew0']
[2025-04-02T21:00:11.264+0000] {standard_task_runner.py:88} INFO - Job 7: Subtask process_log_files
[2025-04-02T21:00:11.327+0000] {task_command.py:423} INFO - Running <TaskInstance: Web_Log_Processing.process_log_files scheduled__2025-04-01T00:00:00+00:00 [running]> on host 4031425a0ee2
[2025-04-02T21:00:11.654+0000] {taskinstance.py:2480} INFO - Exporting env vars: AIRFLOW_CTX_DAG_OWNER='***' AIRFLOW_CTX_DAG_ID='Web_Log_Processing' AIRFLOW_CTX_TASK_ID='process_log_files' AIRFLOW_CTX_EXECUTION_DATE='2025-04-01T00:00:00+00:00' AIRFLOW_CTX_TRY_NUMBER='6' AIRFLOW_CTX_DAG_RUN_ID='scheduled__2025-04-01T00:00:00+00:00'
[2025-04-02T21:00:11.664+0000] {taskinstance.py:2698} ERROR - Task failed with exception
Traceback (most recent call last):
  File "/opt/airflow/dags/w3c.py", line 111, in process_logs
    raise AirflowException("No valid log entries found in the log files.")
airflow.exceptions.AirflowException: No valid log entries found in the log files.

During handling of the above exception, another exception occurred:

Traceback (most recent call last):
  File "/home/airflow/.local/lib/python3.8/site-packages/airflow/models/taskinstance.py", line 433, in _execute_task
    result = execute_callable(context=context, **execute_callable_kwargs)
  File "/home/airflow/.local/lib/python3.8/site-packages/airflow/operators/python.py", line 199, in execute
    return_value = self.execute_callable()
  File "/home/airflow/.local/lib/python3.8/site-packages/airflow/operators/python.py", line 216, in execute_callable
    return self.python_callable(*self.op_args, **self.op_kwargs)
  File "/opt/airflow/dags/w3c.py", line 157, in process_logs
    raise AirflowException(f"Log processing failed: {str(e)}")
airflow.exceptions.AirflowException: Log processing failed: No valid log entries found in the log files.
[2025-04-02T21:00:11.672+0000] {taskinstance.py:1138} INFO - Marking task as UP_FOR_RETRY. dag_id=Web_Log_Processing, task_id=process_log_files, execution_date=20250401T000000, start_date=20250402T210011, end_date=20250402T210011
[2025-04-02T21:00:11.687+0000] {standard_task_runner.py:107} ERROR - Failed to execute job 7 for task process_log_files (Log processing failed: No valid log entries found in the log files.; 561)
[2025-04-02T21:00:11.715+0000] {local_task_job_runner.py:234} INFO - Task exited with return code 1
[2025-04-02T21:00:11.740+0000] {taskinstance.py:3280} INFO - 0 downstream tasks scheduled from follow-on schedule check
