[2025-04-02T16:00:27.477+0000] {taskinstance.py:1956} INFO - Dependencies all met for dep_context=non-requeueable deps ti=<TaskInstance: People_Data_Pipeline.ensure_people_table manual__2025-04-02T15:54:23.186631+00:00 [queued]>
[2025-04-02T16:00:27.490+0000] {taskinstance.py:1956} INFO - Dependencies all met for dep_context=requeueable deps ti=<TaskInstance: People_Data_Pipeline.ensure_people_table manual__2025-04-02T15:54:23.186631+00:00 [queued]>
[2025-04-02T16:00:27.491+0000] {taskinstance.py:2170} INFO - Starting attempt 1 of 3
[2025-04-02T16:00:27.511+0000] {taskinstance.py:2191} INFO - Executing <Task(PythonOperator): ensure_people_table> on 2025-04-02 15:54:23.186631+00:00
[2025-04-02T16:00:27.518+0000] {standard_task_runner.py:60} INFO - Started process 334 to run task
[2025-04-02T16:00:27.523+0000] {standard_task_runner.py:87} INFO - Running: ['***', 'tasks', 'run', 'People_Data_Pipeline', 'ensure_people_table', 'manual__2025-04-02T15:54:23.186631+00:00', '--job-id', '8', '--raw', '--subdir', 'DAGS_FOLDER/people_dag.py', '--cfg-path', '/tmp/tmp6xg2atvm']
[2025-04-02T16:00:27.526+0000] {standard_task_runner.py:88} INFO - Job 8: Subtask ensure_people_table
[2025-04-02T16:00:27.603+0000] {task_command.py:423} INFO - Running <TaskInstance: People_Data_Pipeline.ensure_people_table manual__2025-04-02T15:54:23.186631+00:00 [running]> on host e8d989b91ca4
[2025-04-02T16:00:27.708+0000] {taskinstance.py:2480} INFO - Exporting env vars: AIRFLOW_CTX_DAG_OWNER='***' AIRFLOW_CTX_DAG_ID='People_Data_Pipeline' AIRFLOW_CTX_TASK_ID='ensure_people_table' AIRFLOW_CTX_EXECUTION_DATE='2025-04-02T15:54:23.186631+00:00' AIRFLOW_CTX_TRY_NUMBER='1' AIRFLOW_CTX_DAG_RUN_ID='manual__2025-04-02T15:54:23.186631+00:00'
[2025-04-02T16:00:27.715+0000] {people_dag.py:87} INFO - Attempting to connect to PostgreSQL...
[2025-04-02T16:00:27.732+0000] {people_dag.py:91} ERROR - Failed to ensure people table: The conn_id `postgres_default` isn't defined
[2025-04-02T16:00:27.747+0000] {taskinstance.py:2698} ERROR - Task failed with exception
Traceback (most recent call last):
  File "/opt/airflow/dags/people_dag.py", line 88, in ensure_people_table
    postgres_hook.run(CREATE_PEOPLE_TABLE_SQL)
  File "/home/airflow/.local/lib/python3.8/site-packages/airflow/providers/common/sql/hooks/sql.py", line 391, in run
    with closing(self.get_conn()) as conn:
  File "/home/airflow/.local/lib/python3.8/site-packages/airflow/providers/postgres/hooks/postgres.py", line 128, in get_conn
    conn = deepcopy(self.connection or self.get_connection(conn_id))
  File "/home/airflow/.local/lib/python3.8/site-packages/airflow/hooks/base.py", line 82, in get_connection
    conn = Connection.get_connection_from_secrets(conn_id)
  File "/home/airflow/.local/lib/python3.8/site-packages/airflow/models/connection.py", line 479, in get_connection_from_secrets
    raise AirflowNotFoundException(f"The conn_id `{conn_id}` isn't defined")
airflow.exceptions.AirflowNotFoundException: The conn_id `postgres_default` isn't defined

During handling of the above exception, another exception occurred:

Traceback (most recent call last):
  File "/home/airflow/.local/lib/python3.8/site-packages/airflow/models/taskinstance.py", line 433, in _execute_task
    result = execute_callable(context=context, **execute_callable_kwargs)
  File "/home/airflow/.local/lib/python3.8/site-packages/airflow/operators/python.py", line 199, in execute
    return_value = self.execute_callable()
  File "/home/airflow/.local/lib/python3.8/site-packages/airflow/operators/python.py", line 216, in execute_callable
    return self.python_callable(*self.op_args, **self.op_kwargs)
  File "/opt/airflow/dags/people_dag.py", line 92, in ensure_people_table
    raise AirflowException(f"Failed to ensure people table: {str(e)}")
airflow.exceptions.AirflowException: Failed to ensure people table: The conn_id `postgres_default` isn't defined
[2025-04-02T16:00:27.764+0000] {taskinstance.py:1138} INFO - Marking task as UP_FOR_RETRY. dag_id=People_Data_Pipeline, task_id=ensure_people_table, execution_date=20250402T155423, start_date=20250402T160027, end_date=20250402T160027
[2025-04-02T16:00:27.784+0000] {standard_task_runner.py:107} ERROR - Failed to execute job 8 for task ensure_people_table (Failed to ensure people table: The conn_id `postgres_default` isn't defined; 334)
[2025-04-02T16:00:27.818+0000] {local_task_job_runner.py:234} INFO - Task exited with return code 1
[2025-04-02T16:00:27.846+0000] {taskinstance.py:3280} INFO - 0 downstream tasks scheduled from follow-on schedule check
